Workbook

Sheet 1_Assumptions
A1: Apple Inc. (AAPL) — DCF 假设页（百万美元，US GAAP）
A2: SIC 3571 Electronic Computers ｜ 财年末 0926 ｜ 现价 $326.57 ｜ 评估日 2026-09-11
A3: 蓝色=可编辑输入 黑色=公式 绿色=跨表链接 黄底=判断项（模板不外推，请自行拉开）
A5: 一、情景开关
A6: 选择情景 1=Bull / 2=Base / 3=Bear | B6: 2 | F6: ◀ 改这一格切换全模型情景
A7: 当前情景 | B7: =CHOOSE(B6,"Bull","Base","Bear")
A9: 二、判断项 —— 模板不做外推，三档初始同值，请自行拉开
A10: 假设项 | B10: Bull | C10: Base | D10: Bear | E10: 生效值 | F10: 历史参考
A11: FY2026E 营收增速 | B11: 0.0643 | C11: 0.0643 | D11: 0.0643 | E11: =IF($B$39=1,B44/$B$87-1,CHOOSE($B$6,B11,C11,D11)+$B$35) | F11: ⚠ 锚定开启时本行输入不生效 —— 生效值由已披露季度反推（见上方第三节）
A12: FY2027E 营收增速 | B12: 0.0544 | C12: 0.0544 | D12: 0.0544 | E12: =CHOOSE($B$6,B12,C12,D12)
A13: FY2028E 营收增速 | B13: 0.0446 | C13: 0.0446 | D13: 0.0446 | E13: =CHOOSE($B$6,B13,C13,D13)
A14: FY2029E 营收增速 | B14: 0.0348 | C14: 0.0348 | D14: 0.0348 | E14: =CHOOSE($B$6,B14,C14,D14)
A15: FY2030E 营收增速 | B15: 0.025 | C15: 0.025 | D15: 0.025 | E15: =CHOOSE($B$6,B15,C15,D15)
A17: FY2026E 毛利率 | B17: 0.4575 | C17: 0.4575 | D17: 0.4575 | E17: =IF($B$39=1,1-B46/B44,CHOOSE($B$6,B17,C17,D17)+$B$36) | F17: ⚠ 锚定开启时本行输入不生效 —— 生效值由已披露季度反推（见上方第三节）
A18: FY2027E 毛利率 | B18: 0.4575 | C18: 0.4575 | D18: 0.4575 | E18: =CHOOSE($B$6,B18,C18,D18)
A19: FY2028E 毛利率 | B19: 0.4575 | C19: 0.4575 | D19: 0.4575 | E19: =CHOOSE($B$6,B19,C19,D19)
A20: FY2029E 毛利率 | B20: 0.4575 | C20: 0.4575 | D20: 0.4575 | E20: =CHOOSE($B$6,B20,C20,D20)
A21: FY2030E 毛利率 | B21: 0.4575 | C21: 0.4575 | D21: 0.4575 | E21: =CHOOSE($B$6,B21,C21,D21)
A23: FY2026E 资本开支 / 营收 | B23: 0.0278 | C23: 0.0278 | D23: 0.0278 | E23: =CHOOSE($B$6,B23,C23,D23) | F23: 近3年均值 2.8%
A24: FY2027E 资本开支 / 营收 | B24: 0.0278 | C24: 0.0278 | D24: 0.0278 | E24: =CHOOSE($B$6,B24,C24,D24)
A25: FY2028E 资本开支 / 营收 | B25: 0.0278 | C25: 0.0278 | D25: 0.0278 | E25: =CHOOSE($B$6,B25,C25,D25)
A26: FY2029E 资本开支 / 营收 | B26: 0.0278 | C26: 0.0278 | D26: 0.0278 | E26: =CHOOSE($B$6,B26,C26,D26)
A27: FY2030E 资本开支 / 营收 | B27: 0.0278 | C27: 0.0278 | D27: 0.0278 | E27: =CHOOSE($B$6,B27,C27,D27)
A29: FY2026E SBC / 营收 | B29: 0.02969 | C29: 0.02969 | D29: 0.02969 | E29: =CHOOSE($B$6,B29,C29,D29) | F29: 近3年均值 2.97%｜美股特有的大额非现金费用
A30: FY2027E SBC / 营收 | B30: 0.02969 | C30: 0.02969 | D30: 0.02969 | E30: =CHOOSE($B$6,B30,C30,D30)
A31: FY2028E SBC / 营收 | B31: 0.02969 | C31: 0.02969 | D31: 0.02969 | E31: =CHOOSE($B$6,B31,C31,D31)
A32: FY2029E SBC / 营收 | B32: 0.02969 | C32: 0.02969 | D32: 0.02969 | E32: =CHOOSE($B$6,B32,C32,D32)
A33: FY2030E SBC / 营收 | B33: 0.02969 | C33: 0.02969 | D33: 0.02969 | E33: =CHOOSE($B$6,B33,C33,D33)
A35: 全期营收增速 Δ（敏感性用） | B35: 0 | F35: 加在每一年的生效增速上
A36: 全期毛利率 Δ（敏感性用） | B36: 0 | F36: 加在每一年的生效毛利率上
A38: 三、锚定已披露季度（2025-09-28 ~ 2026-06-27，前 3 个季度实际已确定，首个预测年不再靠增速假设外推）
A39: 锚定开关（1=锚定 0=按增速外推） | B39: 1 | F39: 1 时首个预测年营收 = 已披露实际 ÷ 占比，忽略上方该年的营收增速假设
A40: 已披露期占全年营收比重 | B40: 0.7622 | F40: 近4年同期占比：77.1%｜76.6%｜75.7%｜75.4%｜均值 76.22% 标准差 0.70pp
A41: 剩余期毛利率 | B41: 0.49068 | F41: 默认沿用已披露期毛利率 49.07%；判断剩余期是否改善请自行调整
A42: 已披露期营业收入（实际） | B42: 364357 | F42: 3 个季度合计，取自 10-Q
A43: 已披露期营业成本（实际） | B43: 185575 | F43: 3 个季度合计，取自 10-Q
A44: → 隐含全年营业收入（占比法） | B44: =B42/B40 | F44: 锚定开关=1 时，首个预测年营收即取此值
A45: 〔交叉口径〕隐含全年营业收入（同期同比法） | B45: 483371.34 | F45: 已披露期同比增速 × 上年全年。占比法假设年内形状稳定，同比法假设同比增速延续——两者差得远说明这一年不好锚
A46: → 隐含全年营业成本 | B46: =B43+(B44-B42)*(1-B41)
A48: 四、自动校准假设（从历史推导；可覆盖）
...

Sheet 2_Income
A1: Apple Inc. (AAPL) — Income（百万美元，US GAAP）
A2: B:F = 历史实际（斜体静态，来自 SEC EDGAR） ｜ G:K = 公式预测 ｜ 基数 = FY2025A（F 列）
A4: Income
A5: 科目（百万美元） | B5: FY2021A | C5: FY2022A | D5: FY2023A | E5: FY2024A | F5: FY2025A | G5: FY2026E | H5: FY2027E | I5: FY2028E | J5: FY2029E | K5: FY2030E
A6: Revenue 营业收入 | B6: 365817 | C6: 394328 | D6: 383285 | E6: 391035 | F6: 416161 | G6: =F6*(1+'1_Assumptions'!$E$11+'1_Assumptions'!$B$35) | H6: =G6*(1+'1_Assumptions'!$E$12+'1_Assumptions'!$B$35) | I6: =H6*(1+'1_Assumptions'!$E$13+'1_Assumptions'!$B$35) | J6: =I6*(1+'1_Assumptions'!$E$14+'1_Assumptions'!$B$35) | K6: =J6*(1+'1_Assumptions'!$E$15+'1_Assumptions'!$B$35)
A7: 营收增速 | C7: 0.077938 | D7: -0.028005 | E7: 0.02022 | F7: 0.064255 | G7: =G6/F6-1 | H7: =H6/G6-1 | I7: =I6/H6-1 | J7: =J6/I6-1 | K7: =K6/J6-1
A8: Cost of revenue 营业成本 | B8: 212981 | C8: 223546 | D8: 214137 | E8: 210352 | F8: 220960 | G8: =G6*(1-'1_Assumptions'!$E$17-'1_Assumptions'!$B$36) | H8: =H6*(1-'1_Assumptions'!$E$18-'1_Assumptions'!$B$36) | I8: =I6*(1-'1_Assumptions'!$E$19-'1_Assumptions'!$B$36) | J8: =J6*(1-'1_Assumptions'!$E$20-'1_Assumptions'!$B$36) | K8: =K6*(1-'1_Assumptions'!$E$21-'1_Assumptions'!$B$36)
A9: Gross profit 毛利 | B9: 152836 | C9: 170782 | D9: 169148 | E9: 180683 | F9: 195201 | G9: =G6-G8 | H9: =H6-H8 | I9: =I6-I8 | J9: =J6-J8 | K9: =K6-K8
A10: 毛利率 | B10: 0.417794 | C10: 0.433096 | D10: 0.441311 | E10: 0.462063 | F10: 0.469052 | G10: =G9/G6 | H10: =H9/H6 | I10: =I9/I6 | J10: =J9/J6 | K10: =K9/K6
A11: R&D 研发费用 | B11: 21914 | C11: 26251 | D11: 29915 | E11: 31370 | F11: 34550 | G11: =G6*'1_Assumptions'!$B$49 | H11: =H6*'1_Assumptions'!$B$49 | I11: =I6*'1_Assumptions'!$B$49 | J11: =J6*'1_Assumptions'!$B$49 | K11: =K6*'1_Assumptions'!$B$49
A12: SG&A 销售及管理费用 | B12: 21973 | C12: 25094 | D12: 24932 | E12: 26097 | F12: 27601 | G12: =G6*'1_Assumptions'!$B$50 | H12: =H6*'1_Assumptions'!$B$50 | I12: =I6*'1_Assumptions'!$B$50 | J12: =J6*'1_Assumptions'!$B$50 | K12: =K6*'1_Assumptions'!$B$50
A13: Other operating 其他经营损益 | G13: =G6*'1_Assumptions'!$B$51 | H13: =H6*'1_Assumptions'!$B$51 | I13: =I6*'1_Assumptions'!$B$51 | J13: =J6*'1_Assumptions'!$B$51 | K13: =K6*'1_Assumptions'!$B$51
A14: Operating income (EBIT) 经营利润 | B14: 108949 | C14: 119437 | D14: 114301 | E14: 123216 | F14: 133050 | G14: =G9-G11-G12+G13 | H14: =H9-H11-H12+H13 | I14: =I9-I11-I12+I13 | J14: =J9-J11-J12+J13 | K14: =K9-K11-K12+K13
A15: Interest expense 利息支出 | B15: 2645 | C15: 2931 | D15: 3933 | G15: =('3_Balance'!F18+'3_Balance'!F19+'3_Balance'!F21)*'1_Assumptions'!$B$61 | H15: =('3_Balance'!G18+'3_Balance'!G19+'3_Balance'!G21)*'1_Assumptions'!$B$61 | I15: =('3_Balance'!H18+'3_Balance'!H19+'3_Balance'!H21)*'1_Assumptions'!$B$61 | J15: =('3_Balance'!I18+'3_Balance'!I19+'3_Balance'!I21)*'1_Assumptions'!$B$61 | K15: =('3_Balance'!J18+'3_Balance'!J19+'3_Balance'!J21)*'1_Assumptions'!$B$61
A16: Interest & investment income 利息与投资收益 | G16: =('3_Balance'!F6+'3_Balance'!F7)*'1_Assumptions'!$B$62 | H16: =('3_Balance'!G6+'3_Balance'!G7)*'1_Assumptions'!$B$62 | I16: =('3_Balance'!H6+'3_Balance'!H7)*'1_Assumptions'!$B$62 | J16: =('3_Balance'!I6+'3_Balance'!I7)*'1_Assumptions'!$B$62 | K16: =('3_Balance'!J6+'3_Balance'!J7)*'1_Assumptions'!$B$62
A17: Other non-operating 其他非经营损益 | B17: 258 | C17: -334 | D17: -565 | E17: 269 | F17: -321 | G17: =0 | H17: =0 | I17: =0 | J17: =0 | K17: =0
A18: Pretax income 税前利润 | B18: 109207 | C18: 119103 | D18: 113736 | E18: 123485 | F18: 132729 | G18: =G14-G15+G16+G17 | H18: =H14-H15+H16+H17 | I18: =I14-I15+I16+I17 | J18: =J14-J15+J16+J17 | K18: =K14-K15+K16+K17
A19: Income tax 所得税 | B19: 14527 | C19: 19300 | D19: 16741 | E19: 29749 | F19: 20719 | G19: =G18*'1_Assumptions'!$B$52 | H19: =H18*'1_Assumptions'!$B$52 | I19: =I18*'1_Assumptions'!$B$52 | J19: =J18*'1_Assumptions'!$B$52 | K19: =K18*'1_Assumptions'!$B$52
A20: Net income 净利润 | B20: 94680 | C20: 99803 | D20: 96995 | E20: 93736 | F20: 112010 | G20: =G18-G19 | H20: =H18-H19 | I20: =I18-I19 | J20: =J18-J19 | K20: =K18-K19
A21: less: NCI 少数股东损益 | G21: =G20*'1_Assumptions'!$B$53 | H21: =H20*'1_Assumptions'!$B$53 | I21: =I20*'1_Assumptions'!$B$53 | J21: =J20*'1_Assumptions'!$B$53 | K21: =K20*'1_Assumptions'!$B$53
A22: Net income to parent 归母净利润 | B22: 94680 | C22: 99803 | D22: 96995 | E22: 93736 | F22: 112010 | G22: =G20-G21 | H22: =H20-H21 | I22: =I20-I21 | J22: =J20-J21 | K22: =K20-K21
A23: Diluted shares 摊薄股数（百万股） | B23: 16864.92 | C23: 16325.82 | D23: 15812.55 | E23: 15408.09 | F23: 15004.7 | G23: ='4_CashFlow'!G30 | H23: ='4_CashFlow'!H30 | I23: ='4_CashFlow'!I30 | J23: ='4_CashFlow'!J30 | K23: ='4_CashFlow'!K30
A24: Diluted EPS | G24: =G22/G23 | H24: =H22/H23 | I24: =I22/I23 | J24: =J22/J23 | K24: =K22/K23
A25: P/E（按现价） | G25: ='1_Assumptions'!$B$89/G24 | H25: ='1_Assumptions'!$B$89/H24 | I25: ='1_Assumptions'!$B$89/I24 | J25: ='1_Assumptions'!$B$89/J24 | K25: ='1_Assumptions'!$B$89/K24
A26: （备查）SBC 股份支付 | B26: 7906 | C26: 9038 | D26: 10833 | E26: 11688 | F26: 12863 | G26: =G6*'1_Assumptions'!$E$29 | H26: =H6*'1_Assumptions'!$E$30 | I26: =I6*'1_Assumptions'!$E$31 | J26: =J6*'1_Assumptions'!$E$32 | K26: =K6*'1_Assumptions'!$E$33

Sheet 3_Balance
A1: Apple Inc. (AAPL) — Balance（百万美元，US GAAP）
A2: B:F = 历史实际（斜体静态，来自 SEC EDGAR） ｜ G:K = 公式预测 ｜ 基数 = FY2025A（F 列）
A4: Balance
A5: 科目（百万美元） | B5: FY2021A | C5: FY2022A | D5: FY2023A | E5: FY2024A | F5: FY2025A | G5: FY2026E | H5: FY2027E | I5: FY2028E | J5: FY2029E | K5: FY2030E
A6: Cash & equivalents 现金 | B6: 34940 | C6: 23646 | D6: 29965 | E6: 29943 | F6: 35934 | G6: ='4_CashFlow'!G27 | H6: ='4_CashFlow'!H27 | I6: ='4_CashFlow'!I27 | J6: ='4_CashFlow'!J27 | K6: ='4_CashFlow'!K27
A7: Short-term investments 短期投资 | B7: 27699 | C7: 24658 | D7: 31590 | E7: 35228 | F7: 18763 | G7: =F7 | H7: =G7 | I7: =H7 | J7: =I7 | K7: =J7
A8: Accounts receivable 应收账款 | B8: 26278 | C8: 28184 | D8: 29508 | E8: 33410 | F8: 39777 | G8: ='2_Income'!G6*'1_Assumptions'!$B$56/365 | H8: ='2_Income'!H6*'1_Assumptions'!$B$56/365 | I8: ='2_Income'!I6*'1_Assumptions'!$B$56/365 | J8: ='2_Income'!J6*'1_Assumptions'!$B$56/365 | K8: ='2_Income'!K6*'1_Assumptions'!$B$56/365
A9: Inventory 存货 | B9: 6580 | C9: 4946 | D9: 6331 | E9: 7286 | F9: 5718 | G9: ='2_Income'!G8*'1_Assumptions'!$B$57/365 | H9: ='2_Income'!H8*'1_Assumptions'!$B$57/365 | I9: ='2_Income'!I8*'1_Assumptions'!$B$57/365 | J9: ='2_Income'!J8*'1_Assumptions'!$B$57/365 | K9: ='2_Income'!K8*'1_Assumptions'!$B$57/365
A10: Other current assets 其他流动资产 | B10: 39339 | C10: 53971 | D10: 46172 | E10: 47120 | F10: 47765 | G10: ='2_Income'!G6*'1_Assumptions'!$B$54 | H10: ='2_Income'!H6*'1_Assumptions'!$B$54 | I10: ='2_Income'!I6*'1_Assumptions'!$B$54 | J10: ='2_Income'!J6*'1_Assumptions'!$B$54 | K10: ='2_Income'!K6*'1_Assumptions'!$B$54
A11: Total current assets 流动资产合计 | G11: =SUM(G6:G10) | H11: =SUM(H6:H10) | I11: =SUM(I6:I10) | J11: =SUM(J6:J10) | K11: =SUM(K6:K10)
A12: PP&E, net 固定资产净额 | B12: 39440 | C12: 42117 | D12: 43715 | E12: 45680 | F12: 49834 | G12: =F12-'4_CashFlow'!G16-'4_CashFlow'!G7 | H12: =G12-'4_CashFlow'!H16-'4_CashFlow'!H7 | I12: =H12-'4_CashFlow'!I16-'4_CashFlow'!I7 | J12: =I12-'4_CashFlow'!J16-'4_CashFlow'!J7 | K12: =J12-'4_CashFlow'!K16-'4_CashFlow'!K7
A13: Long-term investments 长期投资 | B13: 127877 | C13: 120805 | D13: 100544 | E13: 91479 | F13: 77723 | G13: =F13 | H13: =G13 | I13: =H13 | J13: =I13 | K13: =J13
A14: Goodwill & intangibles 商誉与无形资产 | G14: =F14-'4_CashFlow'!G8 | H14: =G14-'4_CashFlow'!H8 | I14: =H14-'4_CashFlow'!I8 | J14: =I14-'4_CashFlow'!J8 | K14: =J14-'4_CashFlow'!K8
A15: Other non-current assets 其他非流动资产 | B15: 48849 | C15: 54428 | D15: 64758 | E15: 74834 | F15: 83727 | G15: =F15 | H15: =G15 | I15: =H15 | J15: =I15 | K15: =J15
A16: Total assets 资产总计 | G16: =G11+SUM(G12:G15) | H16: =H11+SUM(H12:H15) | I16: =I11+SUM(I12:I15) | J16: =J11+SUM(J12:J15) | K16: =K11+SUM(K12:K15)
A17: Liabilities & equity 负债与所有者权益
A18: Short-term borrowings 短期借款 | B18: 6000 | C18: 9982 | D18: 5985 | E18: 9967 | F18: 7979 | G18: =F18+'4_CashFlow'!G23 | H18: =G18+'4_CashFlow'!H23 | I18: =H18+'4_CashFlow'!I23 | J18: =I18+'4_CashFlow'!J23 | K18: =J18+'4_CashFlow'!K23
A19: Current portion of LT debt 一年内到期债务 | B19: 9613 | C19: 11128 | D19: 9822 | E19: 10912 | F19: 12350 | G19: =F19 | H19: =G19 | I19: =H19 | J19: =I19 | K19: =J19
A20: Accounts payable 应付账款 | B20: 54763 | C20: 64115 | D20: 62611 | E20: 68960 | F20: 69860 | G20: ='2_Income'!G8*'1_Assumptions'!$B$58/365 | H20: ='2_Income'!H8*'1_Assumptions'!$B$58/365 | I20: ='2_Income'!I8*'1_Assumptions'!$B$58/365 | J20: ='2_Income'!J8*'1_Assumptions'!$B$58/365 | K20: ='2_Income'!K8*'1_Assumptions'!$B$58/365
A21: Long-term debt 长期债务 | B21: 109106 | C21: 98959 | D21: 95281 | E21: 85750 | F21: 78328 | G21: =F21 | H21: =G21 | I21: =H21 | J21: =I21 | K21: =J21
A22: Other current liabilities 其他流动负债 | B22: 55105 | C22: 68757 | D22: 66890 | E22: 86553 | F22: 75442 | G22: ='2_Income'!G6*'1_Assumptions'!$B$55 | H22: ='2_Income'!H6*'1_Assumptions'!$B$55 | I22: ='2_Income'!I6*'1_Assumptions'!$B$55 | J22: ='2_Income'!J6*'1_Assumptions'!$B$55 | K22: ='2_Income'!K6*'1_Assumptions'!$B$55
A23: Other non-current liabilities 其他非流动负债 | B23: 53325 | C23: 49142 | D23: 49848 | E23: 45888 | F23: 41549 | G23: =F23 | H23: =G23 | I23: =H23 | J23: =I23 | K23: =J23
A24: Total liabilities 负债合计 | G24: =SUM(G18:G23) | H24: =SUM(H18:H23) | I24: =SUM(I18:I23) | J24: =SUM(J18:J23) | K24: =SUM(K18:K23)
A25: Stockholders' equity 归母权益 | B25: 63090 | C25: 50672 | D25: 62146 | E25: 56950 | F25: 73733 | G25: =F25+'2_Income'!G22+'4_CashFlow'!G20+'4_CashFlow'!G21+'4_CashFlow'!G22+'2_Income'!G26 | H25: =G25+'2_Income'!H22+'4_CashFlow'!H20+'4_CashFlow'!H21+'4_CashFlow'!H22+'2_Income'!H26 | I25: =H25+'2_Income'!I22+'4_CashFlow'!I20+'4_CashFlow'!I21+'4_CashFlow'!I22+'2_Income'!I26 | J25: =I25+'2_Income'!J22+'4_CashFlow'!J20+'4_CashFlow'!J21+'4_CashFlow'!J22+'2_Income'!J26 | K25: =J25+'2_Income'!K22+'4_CashFlow'!K20+'4_CashFlow'!K21+'4_CashFlow'!K22+'2_Income'!K26
A26: Noncontrolling interests 少数股东权益 | G26: =F26+'2_Income'!G21 | H26: =G26+'2_Income'!H21 | I26: =H26+'2_Income'!I21 | J26: =I26+'2_Income'!J21 | K26: =J26+'2_Income'!K21
A27: Total equity 权益合计 | G27: =G25+G26 | H27: =H25+H26 | I27: =I25+I26 | J27: =J25+J26 | K27: =K25+K26
A28: Total liabilities & equity 负债和权益总计 | G28: =G24+G27 | H28: =H24+H27 | I28: =I24+I27 | J28: =J24+J27 | K28: =K24+K27
A29: ★ 平衡校验 = 资产 −（负债+权益） | G29: =G16-G28 | H29: =H16-H28 | I29: =I16-I28 | J29: =J16-J28 | K29: =K16-K28
A30: Net debt 净负债 | G30: =G18+G19+G21-G6-G7 | H30: =H18+H19+H21-H6-H7 | I30: =I18+I19+I21-I6-I7 | J30: =J18+J19+J21-J6-J7 | K30: =K18+K19+K21-K6-K7
A31: NWC 营运资本 | G31: =G8+G9+G10-G20-G22 | H31: =H8+H9+H10-H20-H22 | I31: =I8+I9+I10-I20-I22 | J31: =J8+J9+J10-J20-J22 | K31: =K8+K9+K10-K20-K22
A32: 〔备查〕研发摊销 R&D amortization | G32: =F33/'1_Assumptions'!$B$110 | H32: =G33/'1_Assumptions'!$B$110 | I32: =H33/'1_Assumptions'!$B$110 | J32: =I33/'1_Assumptions'!$B$110 | K32: =J33/'1_Assumptions'!$B$110
A33: 〔备查〕研发资本 Research asset | F33: 92478.2 | G33: =F33+'2_Income'!G11-G32 | H33: =G33+'2_Income'!H11-H32 | I33: =H33+'2_Income'!I11-I32 | J33: =I33+'2_Income'!J11-J32 | K33: =J33+'2_Income'!K11-K32
A34: 〔备查〕投入资本 IC（申报口径） | G34: =G31+G12+G14+G15-G23 | H34: =H31+H12+H14+H15-H23 | I34: =I31+I12+I14+I15-I23 | J34: =J31+J12+J14+J15-J23 | K34: =K31+K12+K14+K15-K23
A35: 〔备查〕投入资本 IC（含研发资本） | G35: =G34+IF('1_Assumptions'!$B$109=1,G33,0) | H35: =H34+IF('1_Assumptions'!$B$109=1,H33,0) | I35: =I34+IF('1_Assumptions'!$B$109=1,I33,0) | J35: =J34+IF('1_Assumptions'!$B$109=1,J33,0) | K35: =K34+IF('1_Assumptions'!$B$109=1,K33,0)
A36: 〔备查〕生效投入资本 IC | G36: =G35 | H36: =H35 | I36: =I35 | J36: =J35 | K36: =K35

Sheet 4_CashFlow
A1: Apple Inc. (AAPL) — CashFlow（百万美元，US GAAP）
A2: B:F = 历史实际（斜体静态，来自 SEC EDGAR） ｜ G:K = 公式预测 ｜ 基数 = FY2025A（F 列）
A3: 注：历史列仅填报表已披露科目；营运资本明细变动、循环贷与股数滚动为模型专用行，历史留空。
A4: CashFlow
A5: 科目（百万美元） | B5: FY2021A | C5: FY2022A | D5: FY2023A | E5: FY2024A | F5: FY2025A | G5: FY2026E | H5: FY2027E | I5: FY2028E | J5: FY2029E | K5: FY2030E
A6: Net income 净利润 | B6: 94680 | C6: 99803 | D6: 96995 | E6: 93736 | F6: 112010 | G6: ='2_Income'!G20 | H6: ='2_Income'!H20 | I6: ='2_Income'!I20 | J6: ='2_Income'!J20 | K6: ='2_Income'!K20
A7: + Depreciation 折旧 | B7: 9500 | C7: 8700 | D7: 8500 | E7: 8200 | F7: 8000 | G7: ='3_Balance'!F12*'1_Assumptions'!$B$59 | H7: ='3_Balance'!G12*'1_Assumptions'!$B$59 | I7: ='3_Balance'!H12*'1_Assumptions'!$B$59 | J7: ='3_Balance'!I12*'1_Assumptions'!$B$59 | K7: ='3_Balance'!J12*'1_Assumptions'!$B$59
A8: + Amortization 无形摊销 | B8: 1784 | C8: 2404 | D8: 3019 | E8: 3245 | F8: 3698 | G8: ='2_Income'!G6*'1_Assumptions'!$B$60 | H8: ='2_Income'!H6*'1_Assumptions'!$B$60 | I8: ='2_Income'!I6*'1_Assumptions'!$B$60 | J8: ='2_Income'!J6*'1_Assumptions'!$B$60 | K8: ='2_Income'!K6*'1_Assumptions'!$B$60
A9: + SBC 股份支付 | B9: 7906 | C9: 9038 | D9: 10833 | E9: 11688 | F9: 12863 | G9: ='2_Income'!G26 | H9: ='2_Income'!H26 | I9: ='2_Income'!I26 | J9: ='2_Income'!J26 | K9: ='2_Income'!K26
A10: − ΔAccounts receivable 应收增加 | G10: =-('3_Balance'!G8-'3_Balance'!F8) | H10: =-('3_Balance'!H8-'3_Balance'!G8) | I10: =-('3_Balance'!I8-'3_Balance'!H8) | J10: =-('3_Balance'!J8-'3_Balance'!I8) | K10: =-('3_Balance'!K8-'3_Balance'!J8)
A11: − ΔInventory 存货增加 | G11: =-('3_Balance'!G9-'3_Balance'!F9) | H11: =-('3_Balance'!H9-'3_Balance'!G9) | I11: =-('3_Balance'!I9-'3_Balance'!H9) | J11: =-('3_Balance'!J9-'3_Balance'!I9) | K11: =-('3_Balance'!K9-'3_Balance'!J9)
A12: − ΔOther current assets 其他流动资产增加 | G12: =-('3_Balance'!G10-'3_Balance'!F10) | H12: =-('3_Balance'!H10-'3_Balance'!G10) | I12: =-('3_Balance'!I10-'3_Balance'!H10) | J12: =-('3_Balance'!J10-'3_Balance'!I10) | K12: =-('3_Balance'!K10-'3_Balance'!J10)
A13: + ΔAccounts payable 应付增加 | G13: ='3_Balance'!G20-'3_Balance'!F20 | H13: ='3_Balance'!H20-'3_Balance'!G20 | I13: ='3_Balance'!I20-'3_Balance'!H20 | J13: ='3_Balance'!J20-'3_Balance'!I20 | K13: ='3_Balance'!K20-'3_Balance'!J20
A14: + ΔOther current liabilities 其他流动负债增加 | G14: ='3_Balance'!G22-'3_Balance'!F22 | H14: ='3_Balance'!H22-'3_Balance'!G22 | I14: ='3_Balance'!I22-'3_Balance'!H22 | J14: ='3_Balance'!J22-'3_Balance'!I22 | K14: ='3_Balance'!K22-'3_Balance'!J22
A15: Operating cash flow 经营活动现金流 | B15: 104038 | C15: 122151 | D15: 110543 | E15: 118254 | F15: 111482 | G15: =SUM(G6:G14) | H15: =SUM(H6:H14) | I15: =SUM(I6:I14) | J15: =SUM(J6:J14) | K15: =SUM(K6:K14)
A16: − Capital expenditure 资本开支 | B16: -11085 | C16: -10708 | D16: -10959 | E16: -9447 | F16: -12715 | G16: =-'2_Income'!G6*'1_Assumptions'!$E$23-IF(AND('1_Assumptions'!$B$134>0,1>='1_Assumptions'!$B$133,1<='1_Assumptions'!$B$133+2),'1_Assumptions'!$B$134/3,0) | H16: =-'2_Income'!H6*'1_Assumptions'!$E$24-IF(AND('1_Assumptions'!$B$134>0,2>='1_Assumptions'!$B$133,2<='1_Assumptions'!$B$133+2),'1_Assumptions'!$B$134/3,0) | I16: =-'2_Income'!I6*'1_Assumptions'!$E$25-IF(AND('1_Assumptions'!$B$134>0,3>='1_Assumptions'!$B$133,3<='1_Assumptions'!$B$133+2),'1_Assumptions'!$B$134/3,0) | J16: =-'2_Income'!J6*'1_Assumptions'!$E$26-IF(AND('1_Assumptions'!$B$134>0,4>='1_Assumptions'!$B$133,4<='1_Assumptions'!$B$133+2),'1_Assumptions'!$B$134/3,0) | K16: =-'2_Income'!K6*'1_Assumptions'!$E$27-IF(AND('1_Assumptions'!$B$134>0,5>='1_Assumptions'!$B$133,5<='1_Assumptions'!$B$133+2),'1_Assumptions'!$B$134/3,0)
A17: Investing cash flow 投资活动现金流 | G17: =G16 | H17: =H16 | I17: =I16 | J17: =J16 | K17: =K16
A18: Free cash flow (OCF − capex) 自由现金流 | G18: =G15+G16 | H18: =H15+H16 | I18: =I15+I16 | J18: =J15+J16 | K18: =K15+K16
A19: FCFF（无杠杆自由现金流） | G19: ='2_Income'!G14*(1-'1_Assumptions'!$B$52)+G7+G8+IF('1_Assumptions'!$B$113=1,G9,0)+G16+SUM(G10:G14) | H19: ='2_Income'!H14*(1-'1_Assumptions'!$B$52)+H7+H8+IF('1_Assumptions'!$B$113=1,H9,0)+H16+SUM(H10:H14) | I19: ='2_Income'!I14*(1-'1_Assumptions'!$B$52)+I7+I8+IF('1_Assumptions'!$B$113=1,I9,0)+I16+SUM(I10:I14) | J19: ='2_Income'!J14*(1-'1_Assumptions'!$B$52)+J7+J8+IF('1_Assumptions'!$B$113=1,J9,0)+J16+SUM(J10:J14) | K19: ='2_Income'!K14*(1-'1_Assumptions'!$B$52)+K7+K8+IF('1_Assumptions'!$B$113=1,K9,0)+K16+SUM(K10:K14)
A20: − Dividends 分红 | B20: -14467 | C20: -14841 | D20: -15025 | E20: -15234 | F20: -15421 | G20: =-'2_Income'!G22*'1_Assumptions'!$B$63 | H20: =-'2_Income'!H22*'1_Assumptions'!$B$63 | I20: =-'2_Income'!I22*'1_Assumptions'!$B$63 | J20: =-'2_Income'!J22*'1_Assumptions'!$B$63 | K20: =-'2_Income'!K22*'1_Assumptions'!$B$63
A21: − Share repurchase 回购 | B21: -85971 | C21: -89402 | D21: -77550 | E21: -94949 | F21: -90711 | G21: =-'2_Income'!G6*'1_Assumptions'!$B$128 | H21: =-'2_Income'!H6*'1_Assumptions'!$B$128 | I21: =-'2_Income'!I6*'1_Assumptions'!$B$128 | J21: =-'2_Income'!J6*'1_Assumptions'!$B$128 | K21: =-'2_Income'!K6*'1_Assumptions'!$B$128
A22: + Equity issuance 增发募资净额 | G22: =IF('1_Assumptions'!$B$133=1,'1_Assumptions'!$B$135,0) | H22: =IF('1_Assumptions'!$B$133=2,'1_Assumptions'!$B$135,0) | I22: =IF('1_Assumptions'!$B$133=3,'1_Assumptions'!$B$135,0) | J22: =IF('1_Assumptions'!$B$133=4,'1_Assumptions'!$B$135,0) | K22: =IF('1_Assumptions'!$B$133=5,'1_Assumptions'!$B$135,0)
A23: + Revolver 循环贷净变动 | G23: =IF(G26<'1_Assumptions'!$B$64,'1_Assumptions'!$B$64-G26,IF(AND(G26>'1_Assumptions'!$B$64+'1_Assumptions'!$B$65,'3_Balance'!F18>0),-MIN('3_Balance'!F18,G26-('1_Assumptions'!$B$64+'1_Assumptions'!$B$65)),0)) | H23: =IF(H26<'1_Assumptions'!$B$64,'1_Assumptions'!$B$64-H26,IF(AND(H26>'1_Assumptions'!$B$64+'1_Assumptions'!$B$65,'3_Balance'!G18>0),-MIN('3_Balance'!G18,H26-('1_Assumptions'!$B$64+'1_Assumptions'!$B$65)),0)) | I23: =IF(I26<'1_Assumptions'!$B$64,'1_Assumptions'!$B$64-I26,IF(AND(I26>'1_Assumptions'!$B$64+'1_Assumptions'!$B$65,'3_Balance'!H18>0),-MIN('3_Balance'!H18,I26-('1_Assumptions'!$B$64+'1_Assumptions'!$B$65)),0)) | J23: =IF(J26<'1_Assumptions'!$B$64,'1_Assumptions'!$B$64-J26,IF(AND(J26>'1_Assumptions'!$B$64+'1_Assumptions'!$B$65,'3_Balance'!I18>0),-MIN('3_Balance'!I18,J26-('1_Assumptions'!$B$64+'1_Assumptions'!$B$65)),0)) | K23: =IF(K26<'1_Assumptions'!$B$64,'1_Assumptions'!$B$64-K26,IF(AND(K26>'1_Assumptions'!$B$64+'1_Assumptions'!$B$65,'3_Balance'!J18>0),-MIN('3_Balance'!J18,K26-('1_Assumptions'!$B$64+'1_Assumptions'!$B$65)),0))
A24: Financing cash flow 筹资活动现金流 | G24: =SUM(G20:G23) | H24: =SUM(H20:H23) | I24: =SUM(I20:I23) | J24: =SUM(J20:J23) | K24: =SUM(K20:K23)
A25: Net change in cash 现金净增加 | G25: =G15+G17+G24 | H25: =H15+H17+H24 | I25: =I15+I17+I24 | J25: =J15+J17+J24 | K25: =K15+K17+K24
A26: （辅助）筹资前现金余额 | G26: =F27+G15+G17+G20+G21+G22 | H26: =G27+H15+H17+H20+H21+H22 | I26: =H27+I15+I17+I20+I21+I22 | J26: =I27+J15+J17+J20+J21+J22 | K26: =J27+K15+K17+K20+K21+K22
A27: Ending cash 期末现金 | B27: 34940 | C27: 23646 | D27: 29965 | E27: 29943 | F27: 35934 | G27: =F27+G25 | H27: =G27+H25 | I27: =H27+I25 | J27: =I27+J25 | K27: =J27+K25
A28: 回购股数（百万股） | G28: =-G21/'1_Assumptions'!$B$129 | H28: =-H21/'1_Assumptions'!$B$129 | I28: =-I21/'1_Assumptions'!$B$129 | J28: =-J21/'1_Assumptions'!$B$129 | K28: =-K21/'1_Assumptions'!$B$129
A29: SBC 增发股数（仅在加回口径下） | G29: =IF('1_Assumptions'!$B$113=1,'2_Income'!G26/'1_Assumptions'!$B$129,0) | H29: =IF('1_Assumptions'!$B$113=1,'2_Income'!H26/'1_Assumptions'!$B$129,0) | I29: =IF('1_Assumptions'!$B$113=1,'2_Income'!I26/'1_Assumptions'!$B$129,0) | J29: =IF('1_Assumptions'!$B$113=1,'2_Income'!J26/'1_Assumptions'!$B$129,0) | K29: =IF('1_Assumptions'!$B$113=1,'2_Income'!K26/'1_Assumptions'!$B$129,0)
A30: Diluted shares 摊薄股数（滚动） | B30: 16864.92 | C30: 16325.82 | D30: 15812.55 | E30: 15408.09 | F30: 15004.7 | G30: ='1_Assumptions'!$B$88-G28+G29+IF('1_Assumptions'!$B$133=1,'1_Assumptions'!$B$130,0) | H30: =G30-H28+H29+IF('1_Assumptions'!$B$133=2,'1_Assumptions'!$B$130,0) | I30: =H30-I28+I29+IF('1_Assumptions'!$B$133=3,'1_Assumptions'!$B$130,0) | J30: =I30-J28+J29+IF('1_Assumptions'!$B$133=4,'1_Assumptions'!$B$130,0) | K30: =J30-K28+K29+IF('1_Assumptions'!$B$133=5,'1_Assumptions'!$B$130,0)

Sheet 5_DCF
A1: Apple Inc. (AAPL) — DCF 估值（全公式，百万美元）
A2: 绿色单元格链接自「1_Assumptions」，改假设本页自动重算
A4: 一、折现率 WACC
A5: 无风险利率 Rf（10Y UST） | B5: ='1_Assumptions'!B94
A6: 股权风险溢价 ERP | B6: ='1_Assumptions'!B95
A7: Beta（5年 + Blume） | B7: ='1_Assumptions'!B96
A8: 股权成本 Ke = Rf + β×ERP | B8: =B5+B7*B6
A9: 信用评级（合成，可覆盖） | B9: ='1_Assumptions'!B98 | H9: Altman Z 推导的默认值；已知实际 S&P 评级时请在假设页直接改
A10: 信用利差 | B10: ='1_Assumptions'!B99 | H10: ICE BofA AAA OAS（FRED BAMLC0A1CAAA，2026-09-09）
A11: 债务成本 Kd = Rf + 信用利差 | B11: =B5+B10 | H11: 课程 Ch.4：kd = 无风险利率 + 国家违约利差 + 公司违约利差（美国视为无国家违约利差）
A12: 有效所得税率 t | B12: ='1_Assumptions'!B52
A13: 债务权重 D/(D+E) | B13: ='1_Assumptions'!B101
A14: WACC | B14: =(1-B13)*B8+B13*B11*(1-B12)
A15: 永续增长率 g | B15: ='1_Assumptions'!B103 | H15: Damodaran 规则：g ≤ Rf。当前 Rf 见上方第 1 行
A16: 期中折现开关 | B16: ='1_Assumptions'!B105
A17: SBC 加回开关（0=费用化 1=加回） | B17: ='1_Assumptions'!B113 | H17: 0 = Damodaran（默认）：SBC 是真实成本，不加回；股数也不因 SBC 摊薄
A19: 二、自由现金流 FCFF 与现值
A20: 科目（百万美元） | B20: FY2026E | C20: FY2027E | D20: FY2028E | E20: FY2029E | F20: FY2030E
A21: EBIT（= Operating income） | B21: ='2_Income'!G14 | C21: ='2_Income'!H14 | D21: ='2_Income'!I14 | E21: ='2_Income'!J14 | F21: ='2_Income'!K14
A22: EBIT × (1 − t) | B22: =B21*(1-$B$12) | C22: =C21*(1-$B$12) | D22: =D21*(1-$B$12) | E22: =E21*(1-$B$12) | F22: =F21*(1-$B$12)
A23: + 折旧 | B23: ='4_CashFlow'!G7 | C23: ='4_CashFlow'!H7 | D23: ='4_CashFlow'!I7 | E23: ='4_CashFlow'!J7 | F23: ='4_CashFlow'!K7
A24: + 无形摊销 | B24: ='4_CashFlow'!G8 | C24: ='4_CashFlow'!H8 | D24: ='4_CashFlow'!I8 | E24: ='4_CashFlow'!J8 | F24: ='4_CashFlow'!K8
A25: + SBC（仅在加回口径下） | B25: =IF($B$17=1,'4_CashFlow'!G9,0) | C25: =IF($B$17=1,'4_CashFlow'!H9,0) | D25: =IF($B$17=1,'4_CashFlow'!I9,0) | E25: =IF($B$17=1,'4_CashFlow'!J9,0) | F25: =IF($B$17=1,'4_CashFlow'!K9,0) | H25: 默认 0。加回会同时打开股数的 SBC 摊薄 —— 两件事绑在一起
A26: − 资本开支 | B26: ='4_CashFlow'!G16 | C26: ='4_CashFlow'!H16 | D26: ='4_CashFlow'!I16 | E26: ='4_CashFlow'!J16 | F26: ='4_CashFlow'!K16
A27: 营运资本变动（现金影响） | B27: =SUM('4_CashFlow'!G10:G14) | C27: =SUM('4_CashFlow'!H10:H14) | D27: =SUM('4_CashFlow'!I10:I14) | E27: =SUM('4_CashFlow'!J10:J14) | F27: =SUM('4_CashFlow'!K10:K14)
A28: FCFF | B28: =B22+B23+B24+B25+B26+B27 | C28: =C22+C23+C24+C25+C26+C27 | D28: =D22+D23+D24+D25+D26+D27 | E28: =E22+E23+E24+E25+E26+E27 | F28: =F22+F23+F24+F25+F26+F27
A29: 折现年数 t | B29: 1 | C29: 2 | D29: 3 | E29: 4 | F29: 5
A30: 折现因子 | B30: =1/(1+$B$14)^(B29-0.5*$B$16) | C30: =1/(1+$B$14)^(C29-0.5*$B$16) | D30: =1/(1+$B$14)^(D29-0.5*$B$16) | E30: =1/(1+$B$14)^(E29-0.5*$B$16) | F30: =1/(1+$B$14)^(F29-0.5*$B$16)
A31: FCFF 现值 | B31: =B28*B30 | C31: =C28*C30 | D31: =D28*D30 | E31: =E28*E30 | F31: =F28*F30
A33: 三、终值（Damodaran 一致性：稳态再投资率 = g / ROIC）
A34: 终值所得税率 t_term | B34: ='1_Assumptions'!B104 | H34: 美国联邦法定 21%；永续期不应假设税收优惠永存
A35: FY2030E EBIT | B35: =F21
A36: FY2030E 营运资本 NWC | B36: ='3_Balance'!K31
A37: FY2030E 固定资产净额 | B37: ='3_Balance'!K12
A38: FY2030E 商誉与无形资产 | B38: ='3_Balance'!K14
A39: FY2030E 其他非流动资产 − 其他非流动负债 | B39: ='3_Balance'!K15-'3_Balance'!K23
A40: 投入资本 IC（申报口径） | B40: =B36+B37+B38+B39 | H40: 口径：营运资本 + 固定资产 + 商誉无形 + 其他非流动资产 − 其他非流动负债。旧版只算「营运资本 + 固定资产」，对美股大盘会崩：AAPL 营运资本 −520 亿、商誉无形与其他非流动资产未计入 → IC = −22 亿 → ROIC −4760%，终值被迫降级。本式等价于融资端「有息债务 + 全部权益 − 现金 − 短投 − 长投」；两侧恒等（同一恒等式的重排），属口径自洽性展示，不是独立检错
A41: FY2030E 研发资本（Damodaran） | B41: ='3_Balance'!K33 | H41: 报表外调整项：不进资产总计，只用于投入资本与 ROIC
A42: 生效投入资本 IC | B42: =B40+IF('1_Assumptions'!$B$109=1,B41,0)
A43: 终值 ROIC（计算值） | B43: =B35*(1-B34)/B42 | H43: 把末年超额回报直接永续化
...

Sheet 6_Engine
A1: AAPL — 敏感性引擎（每行 = 一次完整 5 年 FCFF 重算）
A2: 本页是计算中间层，不需手工编辑。「5_DCF」的敏感性表从这里取数；改「1_Assumptions」后本页自动重算。
A4: 基期锚点与生效参数
A5: 基期营业收入 | B5: ='1_Assumptions'!$B$87
A6: 期初固定资产净额 | B6: ='1_Assumptions'!$B$73
A7: 期初商誉与无形 | B7: ='1_Assumptions'!$B$75
A8: 期初研发资本 | B8: ='1_Assumptions'!$B$86
A9: 其他非流动资产净额 | B9: ='1_Assumptions'!$B$76-'1_Assumptions'!$B$82
A10: 期初 NWC | B10: ='1_Assumptions'!$B$70+'1_Assumptions'!$B$71+'1_Assumptions'!$B$72-'1_Assumptions'!$B$77-'1_Assumptions'!$B$78
A11: 经营费用率合计 | B11: ='1_Assumptions'!$B$49+'1_Assumptions'!$B$50
A12: 其他经营损益率 | B12: ='1_Assumptions'!$B$51
A13: 折旧率 | B13: ='1_Assumptions'!$B$59
A14: 无形摊销率 | B14: ='1_Assumptions'!$B$60
A15: 有效税率 | B15: ='1_Assumptions'!$B$52
A16: 研发费用率 | B16: ='1_Assumptions'!$B$49
A17: 研发资本化开关 | B17: ='1_Assumptions'!B109
A18: 研发摊销年限 | B18: ='1_Assumptions'!B110
A19: SBC 加回开关 | B19: ='1_Assumptions'!B113
A20: 终值税率 | B20: ='5_DCF'!B34
A21: WACC（生效） | B21: ='5_DCF'!B14
A22: 永续 g（生效） | B22: ='5_DCF'!B15
A23: 期中折现开关 | B23: ='5_DCF'!B16
A24: 滚动年数 | B24: ='5_DCF'!B58
A25: 净负债 | B25: ='5_DCF'!B60
A26: 非经营资产 | B26: ='5_DCF'!B61
A27: 募资净额现值 | B27: ='5_DCF'!B62
A28: 少数股东方式 | B28: ='5_DCF'!B64
A29: 少数股东占比 | B29: ='5_DCF'!B65
A30: 账面少数股东权益 | B30: ='1_Assumptions'!$B$83
A31: 总股本 | B31: ='5_DCF'!B68
A32: 终值ROIC模式 | B32: ='1_Assumptions'!B111
A33: 终值ROIC溢价 | B33: ='1_Assumptions'!B112
A35: 模块 A：营收增速平移 × 永续增长率 g
A36: Δ 施加在每一年的生效增速上；中心格 Δ=0 且 g=生效值，必然复现基准每股价值
A37: 场景 | B37: 营收增速 Δ | C37: 永续 g | D37: 营收1 | E37: 成本1 | F37: EBIT1 | G37: 折旧1 | H37: 资本开支1 | I37: 期末固资1 | J37: 摊销1 | K37: 商誉无形1 | L37: 研发资本1 | M37: NWC1 | N37: FCFF1 | O37: 营收2 | P37: 成本2 | Q37: EBIT2 | R37: 折旧2 | S37: 资本开支2 | T37: 期末固资2 | U37: 摊销2 | V37: 商誉无形2 | W37: 研发资本2 | X37: NWC2 | Y37: FCFF2 | Z37: 营收3 | AA37: 成本3 | AB37: EBIT3 | AC37: 折旧3 | AD37: 资本开支3 | AE37: 期末固资3 | AF37: 摊销3 | AG37: 商誉无形3 | AH37: 研发资本3 | AI37: NWC3 | AJ37: FCFF3 | AK37: 营收4 | AL37: 成本4 | AM37: EBIT4 | AN37: 折旧4 | AO37: 资本开支4 | AP37: 期末固资4 | AQ37: 摊销4 | AR37: 商誉无形4 | AS37: 研发资本4 | AT37: NWC4 | AU37: FCFF4 | AV37: 营收5 | AW37: 成本5 | AX37: EBIT5 | AY37: 折旧5 | AZ37: 资本开支5 | BA37: 期末固资5 | BB37: 摊销5 | BC37: 商誉无形5 | BD37: 研发资本5 | BE37: NWC5 | BF37: FCFF5 | BG37: PV明确期 | BH37: 终值IC | BI37: 终值ROIC | BJ37: 再投资率 | BK37: 降级 | BL37: 终值NOPAT | BM37: 终值FCFF | BN37: TV | BO37: PV(TV) | BP37: EV0 | BQ37: EV | BR37: 全体权益 | BS37: 少数股东 | BT37: 归母权益 | BU37: 每股
A38: 1-1 | B38: -0.06 | C38: 0.01 | D38: =$B$5*(1+('1_Assumptions'!$E$11+IF('1_Assumptions'!$B$39=1,0,$B38))) | E38: =D38*(1-'1_Assumptions'!$E$17) | F38: =D38-E38-D38*$B$11+D38*$B$12 | G38: =$B$6*$B$13 | H38: =D38*'1_Assumptions'!$E$23 | I38: =$B$6+H38-G38 | J38: =D38*$B$14 | K38: =$B$7-J38 | L38: =$B$8+D38*$B$16-$B$8/$B$18 | M38: =D38*'1_Assumptions'!$B$56/365+E38*'1_Assumptions'!$B$57/365+D38*'1_Assumptions'!$B$54-E38*'1_Assumptions'!$B$58/365-D38*'1_Assumptions'!$B$55 | N38: =F38*(1-$B$15)+G38+J38+IF($B$19=1,D38*'1_Assumptions'!$E$29,0)-H38-(M38-$B$10) | O38: =D38*(1+('1_Assumptions'!$E$12+$B38)) | P38: =O38*(1-'1_Assumptions'!$E$18) | Q38: =O38-P38-O38*$B$11+O38*$B$12 | R38: =I38*$B$13 | S38: =O38*'1_Assumptions'!$E$24 | T38: =I38+S38-R38 | U38: =O38*$B$14 | V38: =K38-U38 | W38: =L38+O38*$B$16-L38/$B$18 | X38: =O38*'1_Assumptions'!$B$56/365+P38*'1_Assumptions'!$B$57/365+O38*'1_Assumptions'!$B$54-P38*'1_Assumptions'!$B$58/365-O38*'1_Assumptions'!$B$55 | Y38: =Q38*(1-$B$15)+R38+U38+IF($B$19=1,O38*'1_Assumptions'!$E$30,0)-S38-(X38-M38) | Z38: =O38*(1+('1_Assumptions'!$E$13+$B38)) | AA38: =Z38*(1-'1_Assumptions'!$E$19) | AB38: =Z38-AA38-Z38*$B$11+Z38*$B$12 | AC38: =T38*$B$13 | AD38: =Z38*'1_Assumptions'!$E$25 | AE38: =T38+AD38-AC38 | AF38: =Z38*$B$14 | AG38: =V38-AF38 | AH38: =W38+Z38*$B$16-W38/$B$18 | AI38: =Z38*'1_Assumptions'!$B$56/365+AA38*'1_Assumptions'!$B$57/365+Z38*'1_Assumptions'!$B$54-AA38*'1_Assumptions'!$B$58/365-Z38*'1_Assumptions'!$B$55 | AJ38: =AB38*(1-$B$15)+AC38+AF38+IF($B$19=1,Z38*'1_Assumptions'!$E$31,0)-AD38-(AI38-X38) | AK38: =Z38*(1+('1_Assumptions'!$E$14+$B38)) | AL38: =AK38*(1-'1_Assumptions'!$E$20) | AM38: =AK38-AL38-AK38*$B$11+AK38*$B$12 | AN38: =AE38*$B$13 | AO38: =AK38*'1_Assumptions'!$E$26 | AP38: =AE38+AO38-AN38 | AQ38: =AK38*$B$14 | AR38: =AG38-AQ38 | AS38: =AH38+AK38*$B$16-AH38/$B$18 | AT38: =AK38*'1_Assumptions'!$B$56/365+AL38*'1_Assumptions'!$B$57/365+AK38*'1_Assumptions'!$B$54-AL38*'1_Assumptions'!$B$58/365-AK38*'1_Assumptions'!$B$55 | AU38: =AM38*(1-$B$15)+AN38+AQ38+IF($B$19=1,AK38*'1_Assumptions'!$E$32,0)-AO38-(AT38-AI38) | AV38: =AK38*(1+('1_Assumptions'!$E$15+$B38)) | AW38: =AV38*(1-'1_Assumptions'!$E$21) | AX38: =AV38-AW38-AV38*$B$11+AV38*$B$12 | AY38: =AP38*$B$13 | AZ38: =AV38*'1_Assumptions'!$E$27 | BA38: =AP38+AZ38-AY38 | BB38: =AV38*$B$14 | BC38: =AR38-BB38 | BD38: =AS38+AV38*$B$16-AS38/$B$18 | BE38: =AV38*'1_Assumptions'!$B$56/365+AW38*'1_Assumptions'!$B$57/365+AV38*'1_Assumptions'!$B$54-AW38*'1_Assumptions'!$B$58/365-AV38*'1_Assumptions'!$B$55 | BF38: =AX38*(1-$B$15)+AY38+BB38+IF($B$19=1,AV38*'1_Assumptions'!$E$33,0)-AZ38-(BE38-AT38) | BG38: =N38/(1+$B$21)^(1-0.5*$B$23)+Y38/(1+$B$21)^(2-0.5*$B$23)+AJ38/(1+$B$21)^(3-0.5*$B$23)+AU38/(1+$B$21)^(4-0.5*$B$23)+BF38/(1+$B$21)^(5-0.5*$B$23) | BH38: =BE38+BA38+BC38+$B$9+IF($B$17=1,BD38,0) | BI38: =IF($B$32=2,$B$21+$B$33,IF(BH38=0,0,BL38/BH38)) | BJ38: =IF(BI38=0,9,$C38/BI38) | BK38: =IF(OR(BH38<=0,BI38<=$B$21,BJ38>=1,BJ38<0),1,0) | BL38: =AX38*(1-$B$20) | BM38: =IF(BK38=1,BL38,AX38*(1+$C38)*(1-$B$20)*(1-BJ38)) | BN38: =IF(BK38=1,BL38/$B$21,BM38/($B$21-$C38)) | BO38: =BN38/(1+$B$21)^(5-0.5*$B$23) | BP38: =BG38+BO38 | BQ38: =BP38*(1+$B$21)^$B$24-N38*$B$24*(1+$B$21)^($B$24/2) | BR38: =BQ38-$B$25+$B$26+$B$27 | BS38: =IF($B$28=1,$B$30,BR38*$B$29) | BT38: =BR38-BS38 | BU38: =BT38/$B$31
A39: 1-2 | B39: -0.06 | C39: 0.0175 | D39: =$B$5*(1+('1_Assumptions'!$E$11+IF('1_Assumptions'!$B$39=1,0,$B39))) | E39: =D39*(1-'1_Assumptions'!$E$17) | F39: =D39-E39-D39*$B$11+D39*$B$12 | G39: =$B$6*$B$13 | H39: =D39*'1_Assumptions'!$E$23 | I39: =$B$6+H39-G39 | J39: =D39*$B$14 | K39: =$B$7-J39 | L39: =$B$8+D39*$B$16-$B$8/$B$18 | M39: =D39*'1_Assumptions'!$B$56/365+E39*'1_Assumptions'!$B$57/365+D39*'1_Assumptions'!$B$54-E39*'1_Assumptions'!$B$58/365-D39*'1_Assumptions'!$B$55 | N39: =F39*(1-$B$15)+G39+J39+IF($B$19=1,D39*'1_Assumptions'!$E$29,0)-H39-(M39-$B$10) | O39: =D39*(1+('1_Assumptions'!$E$12+$B39)) | P39: =O39*(1-'1_Assumptions'!$E$18) | Q39: =O39-P39-O39*$B$11+O39*$B$12 | R39: =I39*$B$13 | S39: =O39*'1_Assumptions'!$E$24 | T39: =I39+S39-R39 | U39: =O39*$B$14 | V39: =K39-U39 | W39: =L39+O39*$B$16-L39/$B$18 | X39: =O39*'1_Assumptions'!$B$56/365+P39*'1_Assumptions'!$B$57/365+O39*'1_Assumptions'!$B$54-P39*'1_Assumptions'!$B$58/365-O39*'1_Assumptions'!$B$55 | Y39: =Q39*(1-$B$15)+R39+U39+IF($B$19=1,O39*'1_Assumptions'!$E$30,0)-S39-(X39-M39) | Z39: =O39*(1+('1_Assumptions'!$E$13+$B39)) | AA39: =Z39*(1-'1_Assumptions'!$E$19) | AB39: =Z39-AA39-Z39*$B$11+Z39*$B$12 | AC39: =T39*$B$13 | AD39: =Z39*'1_Assumptions'!$E$25 | AE39: =T39+AD39-AC39 | AF39: =Z39*$B$14 | AG39: =V39-AF39 | AH39: =W39+Z39*$B$16-W39/$B$18 | AI39: =Z39*'1_Assumptions'!$B$56/365+AA39*'1_Assumptions'!$B$57/365+Z39*'1_Assumptions'!$B$54-AA39*'1_Assumptions'!$B$58/365-Z39*'1_Assumptions'!$B$55 | AJ39: =AB39*(1-$B$15)+AC39+AF39+IF($B$19=1,Z39*'1_Assumptions'!$E$31,0)-AD39-(AI39-X39) | AK39: =Z39*(1+('1_Assumptions'!$E$14+$B39)) | AL39: =AK39*(1-'1_Assumptions'!$E$20) | AM39: =AK39-AL39-AK39*$B$11+AK39*$B$12 | AN39: =AE39*$B$13 | AO39: =AK39*'1_Assumptions'!$E$26 | AP39: =AE39+AO39-AN39 | AQ39: =AK39*$B$14 | AR39: =AG39-AQ39 | AS39: =AH39+AK39*$B$16-AH39/$B$18 | AT39: =AK39*'1_Assumptions'!$B$56/365+AL39*'1_Assumptions'!$B$57/365+AK39*'1_Assumptions'!$B$54-AL39*'1_Assumptions'!$B$58/365-AK39*'1_Assumptions'!$B$55 | AU39: =AM39*(1-$B$15)+AN39+AQ39+IF($B$19=1,AK39*'1_Assumptions'!$E$32,0)-AO39-(AT39-AI39) | AV39: =AK39*(1+('1_Assumptions'!$E$15+$B39)) | AW39: =AV39*(1-'1_Assumptions'!$E$21) | AX39: =AV39-AW39-AV39*$B$11+AV39*$B$12 | AY39: =AP39*$B$13 | AZ39: =AV39*'1_Assumptions'!$E$27 | BA39: =AP39+AZ39-AY39 | BB39: =AV39*$B$14 | BC39: =AR39-BB39 | BD39: =AS39+AV39*$B$16-AS39/$B$18 | BE39: =AV39*'1_Assumptions'!$B$56/365+AW39*'1_Assumptions'!$B$57/365+AV39*'1_Assumptions'!$B$54-AW39*'1_Assumptions'!$B$58/365-AV39*'1_Assumptions'!$B$55 | BF39: =AX39*(1-$B$15)+AY39+BB39+IF($B$19=1,AV39*'1_Assumptions'!$E$33,0)-AZ39-(BE39-AT39) | BG39: =N39/(1+$B$21)^(1-0.5*$B$23)+Y39/(1+$B$21)^(2-0.5*$B$23)+AJ39/(1+$B$21)^(3-0.5*$B$23)+AU39/(1+$B$21)^(4-0.5*$B$23)+BF39/(1+$B$21)^(5-0.5*$B$23) | BH39: =BE39+BA39+BC39+$B$9+IF($B$17=1,BD39,0) | BI39: =IF($B$32=2,$B$21+$B$33,IF(BH39=0,0,BL39/BH39)) | BJ39: =IF(BI39=0,9,$C39/BI39) | BK39: =IF(OR(BH39<=0,BI39<=$B$21,BJ39>=1,BJ39<0),1,0) | BL39: =AX39*(1-$B$20) | BM39: =IF(BK39=1,BL39,AX39*(1+$C39)*(1-$B$20)*(1-BJ39)) | BN39: =IF(BK39=1,BL39/$B$21,BM39/($B$21-$C39)) | BO39: =BN39/(1+$B$21)^(5-0.5*$B$23) | BP39: =BG39+BO39 | BQ39: =BP39*(1+$B$21)^$B$24-N39*$B$24*(1+$B$21)^($B$24/2) | BR39: =BQ39-$B$25+$B$26+$B$27 | BS39: =IF($B$28=1,$B$30,BR39*$B$29) | BT39: =BR39-BS39 | BU39: =BT39/$B$31
A40: 1-3 | B40: -0.06 | C40: 0.025 | D40: =$B$5*(1+('1_Assumptions'!$E$11+IF('1_Assumptions'!$B$39=1,0,$B40))) | E40: =D40*(1-'1_Assumptions'!$E$17) | F40: =D40-E40-D40*$B$11+D40*$B$12 | G40: =$B$6*$B$13 | H40: =D40*'1_Assumptions'!$E$23 | I40: =$B$6+H40-G40 | J40: =D40*$B$14 | K40: =$B$7-J40 | L40: =$B$8+D40*$B$16-$B$8/$B$18 | M40: =D40*'1_Assumptions'!$B$56/365+E40*'1_Assumptions'!$B$57/365+D40*'1_Assumptions'!$B$54-E40*'1_Assumptions'!$B$58/365-D40*'1_Assumptions'!$B$55 | N40: =F40*(1-$B$15)+G40+J40+IF($B$19=1,D40*'1_Assumptions'!$E$29,0)-H40-(M40-$B$10) | O40: =D40*(1+('1_Assumptions'!$E$12+$B40)) | P40: =O40*(1-'1_Assumptions'!$E$18) | Q40: =O40-P40-O40*$B$11+O40*$B$12 | R40: =I40*$B$13 | S40: =O40*'1_Assumptions'!$E$24 | T40: =I40+S40-R40 | U40: =O40*$B$14 | V40: =K40-U40 | W40: =L40+O40*$B$16-L40/$B$18 | X40: =O40*'1_Assumptions'!$B$56/365+P40*'1_Assumptions'!$B$57/365+O40*'1_Assumptions'!$B$54-P40*'1_Assumptions'!$B$58/365-O40*'1_Assumptions'!$B$55 | Y40: =Q40*(1-$B$15)+R40+U40+IF($B$19=1,O40*'1_Assumptions'!$E$30,0)-S40-(X40-M40) | Z40: =O40*(1+('1_Assumptions'!$E$13+$B40)) | AA40: =Z40*(1-'1_Assumptions'!$E$19) | AB40: =Z40-AA40-Z40*$B$11+Z40*$B$12 | AC40: =T40*$B$13 | AD40: =Z40*'1_Assumptions'!$E$25 | AE40: =T40+AD40-AC40 | AF40: =Z40*$B$14 | AG40: =V40-AF40 | AH40: =W40+Z40*$B$16-W40/$B$18 | AI40: =Z40*'1_Assumptions'!$B$56/365+AA40*'1_Assumptions'!$B$57/365+Z40*'1_Assumptions'!$B$54-AA40*'1_Assumptions'!$B$58/365-Z40*'1_Assumptions'!$B$55 | AJ40: =AB40*(1-$B$15)+AC40+AF40+IF($B$19=1,Z40*'1_Assumptions'!$E$31,0)-AD40-(AI40-X40) | AK40: =Z40*(1+('1_Assumptions'!$E$14+$B40)) | AL40: =AK40*(1-'1_Assumptions'!$E$20) | AM40: =AK40-AL40-AK40*$B$11+AK40*$B$12 | AN40: =AE40*$B$13 | AO40: =AK40*'1_Assumptions'!$E$26 | AP40: =AE40+AO40-AN40 | AQ40: =AK40*$B$14 | AR40: =AG40-AQ40 | AS40: =AH40+AK40*$B$16-AH40/$B$18 | AT40: =AK40*'1_Assumptions'!$B$56/365+AL40*'1_Assumptions'!$B$57/365+AK40*'1_Assumptions'!$B$54-AL40*'1_Assumptions'!$B$58/365-AK40*'1_Assumptions'!$B$55 | AU40: =AM40*(1-$B$15)+AN40+AQ40+IF($B$19=1,AK40*'1_Assumptions'!$E$32,0)-AO40-(AT40-AI40) | AV40: =AK40*(1+('1_Assumptions'!$E$15+$B40)) | AW40: =AV40*(1-'1_Assumptions'!$E$21) | AX40: =AV40-AW40-AV40*$B$11+AV40*$B$12 | AY40: =AP40*$B$13 | AZ40: =AV40*'1_Assumptions'!$E$27 | BA40: =AP40+AZ40-AY40 | BB40: =AV40*$B$14 | BC40: =AR40-BB40 | BD40: =AS40+AV40*$B$16-AS40/$B$18 | BE40: =AV40*'1_Assumptions'!$B$56/365+AW40*'1_Assumptions'!$B$57/365+AV40*'1_Assumptions'!$B$54-AW40*'1_Assumptions'!$B$58/365-AV40*'1_Assumptions'!$B$55 | BF40: =AX40*(1-$B$15)+AY40+BB40+IF($B$19=1,AV40*'1_Assumptions'!$E$33,0)-AZ40-(BE40-AT40) | BG40: =N40/(1+$B$21)^(1-0.5*$B$23)+Y40/(1+$B$21)^(2-0.5*$B$23)+AJ40/(1+$B$21)^(3-0.5*$B$23)+AU40/(1+$B$21)^(4-0.5*$B$23)+BF40/(1+$B$21)^(5-0.5*$B$23) | BH40: =BE40+BA40+BC40+$B$9+IF($B$17=1,BD40,0) | BI40: =IF($B$32=2,$B$21+$B$33,IF(BH40=0,0,BL40/BH40)) | BJ40: =IF(BI40=0,9,$C40/BI40) | BK40: =IF(OR(BH40<=0,BI40<=$B$21,BJ40>=1,BJ40<0),1,0) | BL40: =AX40*(1-$B$20) | BM40: =IF(BK40=1,BL40,AX40*(1+$C40)*(1-$B$20)*(1-BJ40)) | BN40: =IF(BK40=1,BL40/$B$21,BM40/($B$21-$C40)) | BO40: =BN40/(1+$B$21)^(5-0.5*$B$23) | BP40: =BG40+BO40 | BQ40: =BP40*(1+$B$21)^$B$24-N40*$B$24*(1+$B$21)^($B$24/2) | BR40: =BQ40-$B$25+$B$26+$B$27 | BS40: =IF($B$28=1,$B$30,BR40*$B$29) | BT40: =BR40-BS40 | BU40: =BT40/$B$31
A41: 1-4 | B41: -0.06 | C41: 0.0325 | D41: =$B$5*(1+('1_Assumptions'!$E$11+IF('1_Assumptions'!$B$39=1,0,$B41))) | E41: =D41*(1-'1_Assumptions'!$E$17) | F41: =D41-E41-D41*$B$11+D41*$B$12 | G41: =$B$6*$B$13 | H41: =D41*'1_Assumptions'!$E$23 | I41: =$B$6+H41-G41 | J41: =D41*$B$14 | K41: =$B$7-J41 | L41: =$B$8+D41*$B$16-$B$8/$B$18 | M41: =D41*'1_Assumptions'!$B$56/365+E41*'1_Assumptions'!$B$57/365+D41*'1_Assumptions'!$B$54-E41*'1_Assumptions'!$B$58/365-D41*'1_Assumptions'!$B$55 | N41: =F41*(1-$B$15)+G41+J41+IF($B$19=1,D41*'1_Assumptions'!$E$29,0)-H41-(M41-$B$10) | O41: =D41*(1+('1_Assumptions'!$E$12+$B41)) | P41: =O41*(1-'1_Assumptions'!$E$18) | Q41: =O41-P41-O41*$B$11+O41*$B$12 | R41: =I41*$B$13 | S41: =O41*'1_Assumptions'!$E$24 | T41: =I41+S41-R41 | U41: =O41*$B$14 | V41: =K41-U41 | W41: =L41+O41*$B$16-L41/$B$18 | X41: =O41*'1_Assumptions'!$B$56/365+P41*'1_Assumptions'!$B$57/365+O41*'1_Assumptions'!$B$54-P41*'1_Assumptions'!$B$58/365-O41*'1_Assumptions'!$B$55 | Y41: =Q41*(1-$B$15)+R41+U41+IF($B$19=1,O41*'1_Assumptions'!$E$30,0)-S41-(X41-M41) | Z41: =O41*(1+('1_Assumptions'!$E$13+$B41)) | AA41: =Z41*(1-'1_Assumptions'!$E$19) | AB41: =Z41-AA41-Z41*$B$11+Z41*$B$12 | AC41: =T41*$B$13 | AD41: =Z41*'1_Assumptions'!$E$25 | AE41: =T41+AD41-AC41 | AF41: =Z41*$B$14 | AG41: =V41-AF41 | AH41: =W41+Z41*$B$16-W41/$B$18 | AI41: =Z41*'1_Assumptions'!$B$56/365+AA41*'1_Assumptions'!$B$57/365+Z41*'1_Assumptions'!$B$54-AA41*'1_Assumptions'!$B$58/365-Z41*'1_Assumptions'!$B$55 | AJ41: =AB41*(1-$B$15)+AC41+AF41+IF($B$19=1,Z41*'1_Assumptions'!$E$31,0)-AD41-(AI41-X41) | AK41: =Z41*(1+('1_Assumptions'!$E$14+$B41)) | AL41: =AK41*(1-'1_Assumptions'!$E$20) | AM41: =AK41-AL41-AK41*$B$11+AK41*$B$12 | AN41: =AE41*$B$13 | AO41: =AK41*'1_Assumptions'!$E$26 | AP41: =AE41+AO41-AN41 | AQ41: =AK41*$B$14 | AR41: =AG41-AQ41 | AS41: =AH41+AK41*$B$16-AH41/$B$18 | AT41: =AK41*'1_Assumptions'!$B$56/365+AL41*'1_Assumptions'!$B$57/365+AK41*'1_Assumptions'!$B$54-AL41*'1_Assumptions'!$B$58/365-AK41*'1_Assumptions'!$B$55 | AU41: =AM41*(1-$B$15)+AN41+AQ41+IF($B$19=1,AK41*'1_Assumptions'!$E$32,0)-AO41-(AT41-AI41) | AV41: =AK41*(1+('1_Assumptions'!$E$15+$B41)) | AW41: =AV41*(1-'1_Assumptions'!$E$21) | AX41: =AV41-AW41-AV41*$B$11+AV41*$B$12 | AY41: =AP41*$B$13 | AZ41: =AV41*'1_Assumptions'!$E$27 | BA41: =AP41+AZ41-AY41 | BB41: =AV41*$B$14 | BC41: =AR41-BB41 | BD41: =AS41+AV41*$B$16-AS41/$B$18 | BE41: =AV41*'1_Assumptions'!$B$56/365+AW41*'1_Assumptions'!$B$57/365+AV41*'1_Assumptions'!$B$54-AW41*'1_Assumptions'!$B$58/365-AV41*'1_Assumptions'!$B$55 | BF41: =AX41*(1-$B$15)+AY41+BB41+IF($B$19=1,AV41*'1_Assumptions'!$E$33,0)-AZ41-(BE41-AT41) | BG41: =N41/(1+$B$21)^(1-0.5*$B$23)+Y41/(1+$B$21)^(2-0.5*$B$23)+AJ41/(1+$B$21)^(3-0.5*$B$23)+AU41/(1+$B$21)^(4-0.5*$B$23)+BF41/(1+$B$21)^(5-0.5*$B$23) | BH41: =BE41+BA41+BC41+$B$9+IF($B$17=1,BD41,0) | BI41: =IF($B$32=2,$B$21+$B$33,IF(BH41=0,0,BL41/BH41)) | BJ41: =IF(BI41=0,9,$C41/BI41) | BK41: =IF(OR(BH41<=0,BI41<=$B$21,BJ41>=1,BJ41<0),1,0) | BL41: =AX41*(1-$B$20) | BM41: =IF(BK41=1,BL41,AX41*(1+$C41)*(1-$B$20)*(1-BJ41)) | BN41: =IF(BK41=1,BL41/$B$21,BM41/($B$21-$C41)) | BO41: =BN41/(1+$B$21)^(5-0.5*$B$23) | BP41: =BG41+BO41 | BQ41: =BP41*(1+$B$21)^$B$24-N41*$B$24*(1+$B$21)^($B$24/2) | BR41: =BQ41-$B$25+$B$26+$B$27 | BS41: =IF($B$28=1,$B$30,BR41*$B$29) | BT41: =BR41-BS41 | BU41: =BT41/$B$31
A42: 1-5 | B42: -0.06 | C42: 0.04 | D42: =$B$5*(1+('1_Assumptions'!$E$11+IF('1_Assumptions'!$B$39=1,0,$B42))) | E42: =D42*(1-'1_Assumptions'!$E$17) | F42: =D42-E42-D42*$B$11+D42*$B$12 | G42: =$B$6*$B$13 | H42: =D42*'1_Assumptions'!$E$23 | I42: =$B$6+H42-G42 | J42: =D42*$B$14 | K42: =$B$7-J42 | L42: =$B$8+D42*$B$16-$B$8/$B$18 | M42: =D42*'1_Assumptions'!$B$56/365+E42*'1_Assumptions'!$B$57/365+D42*'1_Assumptions'!$B$54-E42*'1_Assumptions'!$B$58/365-D42*'1_Assumptions'!$B$55 | N42: =F42*(1-$B$15)+G42+J42+IF($B$19=1,D42*'1_Assumptions'!$E$29,0)-H42-(M42-$B$10) | O42: =D42*(1+('1_Assumptions'!$E$12+$B42)) | P42: =O42*(1-'1_Assumptions'!$E$18) | Q42: =O42-P42-O42*$B$11+O42*$B$12 | R42: =I42*$B$13 | S42: =O42*'1_Assumptions'!$E$24 | T42: =I42+S42-R42 | U42: =O42*$B$14 | V42: =K42-U42 | W42: =L42+O42*$B$16-L42/$B$18 | X42: =O42*'1_Assumptions'!$B$56/365+P42*'1_Assumptions'!$B$57/365+O42*'1_Assumptions'!$B$54-P42*'1_Assumptions'!$B$58/365-O42*'1_Assumptions'!$B$55 | Y42: =Q42*(1-$B$15)+R42+U42+IF($B$19=1,O42*'1_Assumptions'!$E$30,0)-S42-(X42-M42) | Z42: =O42*(1+('1_Assumptions'!$E$13+$B42)) | AA42: =Z42*(1-'1_Assumptions'!$E$19) | AB42: =Z42-AA42-Z42*$B$11+Z42*$B$12 | AC42: =T42*$B$13 | AD42: =Z42*'1_Assumptions'!$E$25 | AE42: =T42+AD42-AC42 | AF42: =Z42*$B$14 | AG42: =V42-AF42 | AH42: =W42+Z42*$B$16-W42/$B$18 | AI42: =Z42*'1_Assumptions'!$B$56/365+AA42*'1_Assumptions'!$B$57/365+Z42*'1_Assumptions'!$B$54-AA42*'1_Assumptions'!$B$58/365-Z42*'1_Assumptions'!$B$55 | AJ42: =AB42*(1-$B$15)+AC42+AF42+IF($B$19=1,Z42*'1_Assumptions'!$E$31,0)-AD42-(AI42-X42) | AK42: =Z42*(1+('1_Assumptions'!$E$14+$B42)) | AL42: =AK42*(1-'1_Assumptions'!$E$20) | AM42: =AK42-AL42-AK42*$B$11+AK42*$B$12 | AN42: =AE42*$B$13 | AO42: =AK42*'1_Assumptions'!$E$26 | AP42: =AE42+AO42-AN42 | AQ42: =AK42*$B$14 | AR42: =AG42-AQ42 | AS42: =AH42+AK42*$B$16-AH42/$B$18 | AT42: =AK42*'1_Assumptions'!$B$56/365+AL42*'1_Assumptions'!$B$57/365+AK42*'1_Assumptions'!$B$54-AL42*'1_Assumptions'!$B$58/365-AK42*'1_Assumptions'!$B$55 | AU42: =AM42*(1-$B$15)+AN42+AQ42+IF($B$19=1,AK42*'1_Assumptions'!$E$32,0)-AO42-(AT42-AI42) | AV42: =AK42*(1+('1_Assumptions'!$E$15+$B42)) | AW42: =AV42*(1-'1_Assumptions'!$E$21) | AX42: =AV42-AW42-AV42*$B$11+AV42*$B$12 | AY42: =AP42*$B$13 | AZ42: =AV42*'1_Assumptions'!$E$27 | BA42: =AP42+AZ42-AY42 | BB42: =AV42*$B$14 | BC42: =AR42-BB42 | BD42: =AS42+AV42*$B$16-AS42/$B$18 | BE42: =AV42*'1_Assumptions'!$B$56/365+AW42*'1_Assumptions'!$B$57/365+AV42*'1_Assumptions'!$B$54-AW42*'1_Assumptions'!$B$58/365-AV42*'1_Assumptions'!$B$55 | BF42: =AX42*(1-$B$15)+AY42+BB42+IF($B$19=1,AV42*'1_Assumptions'!$E$33,0)-AZ42-(BE42-AT42) | BG42: =N42/(1+$B$21)^(1-0.5*$B$23)+Y42/(1+$B$21)^(2-0.5*$B$23)+AJ42/(1+$B$21)^(3-0.5*$B$23)+AU42/(1+$B$21)^(4-0.5*$B$23)+BF42/(1+$B$21)^(5-0.5*$B$23) | BH42: =BE42+BA42+BC42+$B$9+IF($B$17=1,BD42,0) | BI42: =IF($B$32=2,$B$21+$B$33,IF(BH42=0,0,BL42/BH42)) | BJ42: =IF(BI42=0,9,$C42/BI42) | BK42: =IF(OR(BH42<=0,BI42<=$B$21,BJ42>=1,BJ42<0),1,0) | BL42: =AX42*(1-$B$20) | BM42: =IF(BK42=1,BL42,AX42*(1+$C42)*(1-$B$20)*(1-BJ42)) | BN42: =IF(BK42=1,BL42/$B$21,BM42/($B$21-$C42)) | BO42: =BN42/(1+$B$21)^(5-0.5*$B$23) | BP42: =BG42+BO42 | BQ42: =BP42*(1+$B$21)^$B$24-N42*$B$24*(1+$B$21)^($B$24/2) | BR42: =BQ42-$B$25+$B$26+$B$27 | BS42: =IF($B$28=1,$B$30,BR42*$B$29) | BT42: =BR42-BS42 | BU42: =BT42/$B$31
...

Sheet 7_Ratios
A1: AAPL — 主要财务比率与杜邦分析（百万美元）
A2: 全部为活公式，取自三张报表；改「1_Assumptions」本页与下方图表自动重算。历史列为实际、预测列为模型输出。
A4: 一、盈利能力 Profitability
A5: 指标 | B5: FY2021A | C5: FY2022A | D5: FY2023A | E5: FY2024A | F5: FY2025A | G5: FY2026E | H5: FY2027E | I5: FY2028E | J5: FY2029E | K5: FY2030E
A6: Gross margin 毛利率 | B6: =IFERROR('2_Income'!B9/'2_Income'!B6,"") | C6: =IFERROR('2_Income'!C9/'2_Income'!C6,"") | D6: =IFERROR('2_Income'!D9/'2_Income'!D6,"") | E6: =IFERROR('2_Income'!E9/'2_Income'!E6,"") | F6: =IFERROR('2_Income'!F9/'2_Income'!F6,"") | G6: =IFERROR('2_Income'!G9/'2_Income'!G6,"") | H6: =IFERROR('2_Income'!H9/'2_Income'!H6,"") | I6: =IFERROR('2_Income'!I9/'2_Income'!I6,"") | ... K6: =IFERROR('2_Income'!K9/'2_Income'!K6,"")
A7: EBIT margin 经营利润率 | B7: =IFERROR('2_Income'!B14/'2_Income'!B6,"") | C7: =IFERROR('2_Income'!C14/'2_Income'!C6,"") | D7: =IFERROR('2_Income'!D14/'2_Income'!D6,"") | E7: =IFERROR('2_Income'!E14/'2_Income'!E6,"") | F7: =IFERROR('2_Income'!F14/'2_Income'!F6,"") | G7: =IFERROR('2_Income'!G14/'2_Income'!G6,"") | H7: =IFERROR('2_Income'!H14/'2_Income'!H6,"") | I7: =IFERROR('2_Income'!I14/'2_Income'!I6,"") | ... K7: =IFERROR('2_Income'!K14/'2_Income'!K6,"")
A8: Net margin 归母净利率 | B8: =IFERROR('2_Income'!B22/'2_Income'!B6,"") | C8: =IFERROR('2_Income'!C22/'2_Income'!C6,"") | D8: =IFERROR('2_Income'!D22/'2_Income'!D6,"") | E8: =IFERROR('2_Income'!E22/'2_Income'!E6,"") | F8: =IFERROR('2_Income'!F22/'2_Income'!F6,"") | G8: =IFERROR('2_Income'!G22/'2_Income'!G6,"") | H8: =IFERROR('2_Income'!H22/'2_Income'!H6,"") | I8: =IFERROR('2_Income'!I22/'2_Income'!I6,"") | ... K8: =IFERROR('2_Income'!K22/'2_Income'!K6,"")
A9: SBC / Revenue 股份支付占营收 | B9: =IFERROR('2_Income'!B26/'2_Income'!B6,"") | C9: =IFERROR('2_Income'!C26/'2_Income'!C6,"") | D9: =IFERROR('2_Income'!D26/'2_Income'!D6,"") | E9: =IFERROR('2_Income'!E26/'2_Income'!E6,"") | F9: =IFERROR('2_Income'!F26/'2_Income'!F6,"") | G9: =IFERROR('2_Income'!G26/'2_Income'!G6,"") | H9: =IFERROR('2_Income'!H26/'2_Income'!H6,"") | I9: =IFERROR('2_Income'!I26/'2_Income'!I6,"") | ... K9: =IFERROR('2_Income'!K26/'2_Income'!K6,"")
A10: ROE（归母 / 平均权益） | B10: =IFERROR('2_Income'!B22/'3_Balance'!B25,"") | C10: =IFERROR('2_Income'!C22/AVERAGE('3_Balance'!B25,'3_Balance'!C25),"") | D10: =IFERROR('2_Income'!D22/AVERAGE('3_Balance'!C25,'3_Balance'!D25),"") | E10: =IFERROR('2_Income'!E22/AVERAGE('3_Balance'!D25,'3_Balance'!E25),"") | F10: =IFERROR('2_Income'!F22/AVERAGE('3_Balance'!E25,'3_Balance'!F25),"") | G10: =IFERROR('2_Income'!G22/AVERAGE('3_Balance'!F25,'3_Balance'!G25),"") | H10: =IFERROR('2_Income'!H22/AVERAGE('3_Balance'!G25,'3_Balance'!H25),"") | I10: =IFERROR('2_Income'!I22/AVERAGE('3_Balance'!H25,'3_Balance'!I25),"") | J10: =IFERROR('2_Income'!J22/AVERAGE('3_Balance'!I25,'3_Balance'!J25),"") | K10: =IFERROR('2_Income'!K22/AVERAGE('3_Balance'!J25,'3_Balance'!K25),"")
A11: ROA（净利 / 平均总资产） | B11: =IFERROR('2_Income'!B20/'3_Balance'!B16,"") | C11: =IFERROR('2_Income'!C20/AVERAGE('3_Balance'!B16,'3_Balance'!C16),"") | D11: =IFERROR('2_Income'!D20/AVERAGE('3_Balance'!C16,'3_Balance'!D16),"") | E11: =IFERROR('2_Income'!E20/AVERAGE('3_Balance'!D16,'3_Balance'!E16),"") | F11: =IFERROR('2_Income'!F20/AVERAGE('3_Balance'!E16,'3_Balance'!F16),"") | G11: =IFERROR('2_Income'!G20/AVERAGE('3_Balance'!F16,'3_Balance'!G16),"") | H11: =IFERROR('2_Income'!H20/AVERAGE('3_Balance'!G16,'3_Balance'!H16),"") | I11: =IFERROR('2_Income'!I20/AVERAGE('3_Balance'!H16,'3_Balance'!I16),"") | J11: =IFERROR('2_Income'!J20/AVERAGE('3_Balance'!I16,'3_Balance'!J16),"") | K11: =IFERROR('2_Income'!K20/AVERAGE('3_Balance'!J16,'3_Balance'!K16),"")
A12: ROIC（税后 / 生效投入资本） | B12: =IFERROR('2_Income'!B14*(1-'5_DCF'!$B$34)/'3_Balance'!B36,"") | C12: =IFERROR('2_Income'!C14*(1-'5_DCF'!$B$34)/'3_Balance'!C36,"") | D12: =IFERROR('2_Income'!D14*(1-'5_DCF'!$B$34)/'3_Balance'!D36,"") | E12: =IFERROR('2_Income'!E14*(1-'5_DCF'!$B$34)/'3_Balance'!E36,"") | F12: =IFERROR('2_Income'!F14*(1-'5_DCF'!$B$34)/'3_Balance'!F36,"") | G12: =IFERROR('2_Income'!G14*(1-'5_DCF'!$B$34)/'3_Balance'!G36,"") | H12: =IFERROR('2_Income'!H14*(1-'5_DCF'!$B$34)/'3_Balance'!H36,"") | I12: =IFERROR('2_Income'!I14*(1-'5_DCF'!$B$34)/'3_Balance'!I36,"") | ... K12: =IFERROR('2_Income'!K14*(1-'5_DCF'!$B$34)/'3_Balance'!K36,"")
A13: WACC（基准线） | B13: ='5_DCF'!$B$14 | C13: ='5_DCF'!$B$14 | D13: ='5_DCF'!$B$14 | E13: ='5_DCF'!$B$14 | F13: ='5_DCF'!$B$14 | G13: ='5_DCF'!$B$14 | H13: ='5_DCF'!$B$14 | I13: ='5_DCF'!$B$14 | ... K13: ='5_DCF'!$B$14
A14: ★ 价值利差 ROIC − WACC | B14: =IFERROR(B12-B13,"") | C14: =IFERROR(C12-C13,"") | D14: =IFERROR(D12-D13,"") | E14: =IFERROR(E12-E13,"") | F14: =IFERROR(F12-F13,"") | G14: =IFERROR(G12-G13,"") | H14: =IFERROR(H12-H13,"") | I14: =IFERROR(I12-I13,"") | ... K14: =IFERROR(K12-K13,"")
A16: 二、营运效率 Efficiency
A17: 指标 | B17: FY2021A | C17: FY2022A | D17: FY2023A | E17: FY2024A | F17: FY2025A | G17: FY2026E | H17: FY2027E | I17: FY2028E | J17: FY2029E | K17: FY2030E
A18: DSO 应收周转天数 | B18: =IFERROR('3_Balance'!B8/'2_Income'!B6*365,"") | C18: =IFERROR('3_Balance'!C8/'2_Income'!C6*365,"") | D18: =IFERROR('3_Balance'!D8/'2_Income'!D6*365,"") | E18: =IFERROR('3_Balance'!E8/'2_Income'!E6*365,"") | F18: =IFERROR('3_Balance'!F8/'2_Income'!F6*365,"") | G18: =IFERROR('3_Balance'!G8/'2_Income'!G6*365,"") | H18: =IFERROR('3_Balance'!H8/'2_Income'!H6*365,"") | I18: =IFERROR('3_Balance'!I8/'2_Income'!I6*365,"") | ... K18: =IFERROR('3_Balance'!K8/'2_Income'!K6*365,"")
A19: DIO 存货周转天数 | B19: =IFERROR('3_Balance'!B9/'2_Income'!B8*365,"") | C19: =IFERROR('3_Balance'!C9/'2_Income'!C8*365,"") | D19: =IFERROR('3_Balance'!D9/'2_Income'!D8*365,"") | E19: =IFERROR('3_Balance'!E9/'2_Income'!E8*365,"") | F19: =IFERROR('3_Balance'!F9/'2_Income'!F8*365,"") | G19: =IFERROR('3_Balance'!G9/'2_Income'!G8*365,"") | H19: =IFERROR('3_Balance'!H9/'2_Income'!H8*365,"") | I19: =IFERROR('3_Balance'!I9/'2_Income'!I8*365,"") | ... K19: =IFERROR('3_Balance'!K9/'2_Income'!K8*365,"")
A20: DPO 应付周转天数 | B20: =IFERROR('3_Balance'!B20/'2_Income'!B8*365,"") | C20: =IFERROR('3_Balance'!C20/'2_Income'!C8*365,"") | D20: =IFERROR('3_Balance'!D20/'2_Income'!D8*365,"") | E20: =IFERROR('3_Balance'!E20/'2_Income'!E8*365,"") | F20: =IFERROR('3_Balance'!F20/'2_Income'!F8*365,"") | G20: =IFERROR('3_Balance'!G20/'2_Income'!G8*365,"") | H20: =IFERROR('3_Balance'!H20/'2_Income'!H8*365,"") | I20: =IFERROR('3_Balance'!I20/'2_Income'!I8*365,"") | ... K20: =IFERROR('3_Balance'!K20/'2_Income'!K8*365,"")
A21: ★ 现金转换周期 CCC | B21: =IFERROR(B18+B19-B20,"") | C21: =IFERROR(C18+C19-C20,"") | D21: =IFERROR(D18+D19-D20,"") | E21: =IFERROR(E18+E19-E20,"") | F21: =IFERROR(F18+F19-F20,"") | G21: =IFERROR(G18+G19-G20,"") | H21: =IFERROR(H18+H19-H20,"") | I21: =IFERROR(I18+I19-I20,"") | ... K21: =IFERROR(K18+K19-K20,"")
A22: 总资产周转率 | B22: =IFERROR('2_Income'!B6/'3_Balance'!B16,"") | C22: =IFERROR('2_Income'!C6/AVERAGE('3_Balance'!B16,'3_Balance'!C16),"") | D22: =IFERROR('2_Income'!D6/AVERAGE('3_Balance'!C16,'3_Balance'!D16),"") | E22: =IFERROR('2_Income'!E6/AVERAGE('3_Balance'!D16,'3_Balance'!E16),"") | F22: =IFERROR('2_Income'!F6/AVERAGE('3_Balance'!E16,'3_Balance'!F16),"") | G22: =IFERROR('2_Income'!G6/AVERAGE('3_Balance'!F16,'3_Balance'!G16),"") | H22: =IFERROR('2_Income'!H6/AVERAGE('3_Balance'!G16,'3_Balance'!H16),"") | I22: =IFERROR('2_Income'!I6/AVERAGE('3_Balance'!H16,'3_Balance'!I16),"") | J22: =IFERROR('2_Income'!J6/AVERAGE('3_Balance'!I16,'3_Balance'!J16),"") | K22: =IFERROR('2_Income'!K6/AVERAGE('3_Balance'!J16,'3_Balance'!K16),"")
A23: 固定资产周转率 | B23: =IFERROR('2_Income'!B6/'3_Balance'!B12,"") | C23: =IFERROR('2_Income'!C6/AVERAGE('3_Balance'!B12,'3_Balance'!C12),"") | D23: =IFERROR('2_Income'!D6/AVERAGE('3_Balance'!C12,'3_Balance'!D12),"") | E23: =IFERROR('2_Income'!E6/AVERAGE('3_Balance'!D12,'3_Balance'!E12),"") | F23: =IFERROR('2_Income'!F6/AVERAGE('3_Balance'!E12,'3_Balance'!F12),"") | G23: =IFERROR('2_Income'!G6/AVERAGE('3_Balance'!F12,'3_Balance'!G12),"") | H23: =IFERROR('2_Income'!H6/AVERAGE('3_Balance'!G12,'3_Balance'!H12),"") | I23: =IFERROR('2_Income'!I6/AVERAGE('3_Balance'!H12,'3_Balance'!I12),"") | J23: =IFERROR('2_Income'!J6/AVERAGE('3_Balance'!I12,'3_Balance'!J12),"") | K23: =IFERROR('2_Income'!K6/AVERAGE('3_Balance'!J12,'3_Balance'!K12),"")
A25: 三、偿债与资本结构 Leverage
A26: 指标 | B26: FY2021A | C26: FY2022A | D26: FY2023A | E26: FY2024A | F26: FY2025A | G26: FY2026E | H26: FY2027E | I26: FY2028E | J26: FY2029E | K26: FY2030E
A27: 资产负债率 | B27: =IFERROR('3_Balance'!B24/'3_Balance'!B16,"") | C27: =IFERROR('3_Balance'!C24/'3_Balance'!C16,"") | D27: =IFERROR('3_Balance'!D24/'3_Balance'!D16,"") | E27: =IFERROR('3_Balance'!E24/'3_Balance'!E16,"") | F27: =IFERROR('3_Balance'!F24/'3_Balance'!F16,"") | G27: =IFERROR('3_Balance'!G24/'3_Balance'!G16,"") | H27: =IFERROR('3_Balance'!H24/'3_Balance'!H16,"") | I27: =IFERROR('3_Balance'!I24/'3_Balance'!I16,"") | ... K27: =IFERROR('3_Balance'!K24/'3_Balance'!K16,"")
A28: 净负债 / 归母权益 | B28: =IFERROR('3_Balance'!B30/'3_Balance'!B25,"") | C28: =IFERROR('3_Balance'!C30/'3_Balance'!C25,"") | D28: =IFERROR('3_Balance'!D30/'3_Balance'!D25,"") | E28: =IFERROR('3_Balance'!E30/'3_Balance'!E25,"") | F28: =IFERROR('3_Balance'!F30/'3_Balance'!F25,"") | G28: =IFERROR('3_Balance'!G30/'3_Balance'!G25,"") | H28: =IFERROR('3_Balance'!H30/'3_Balance'!H25,"") | I28: =IFERROR('3_Balance'!I30/'3_Balance'!I25,"") | ... K28: =IFERROR('3_Balance'!K30/'3_Balance'!K25,"")
A29: 有息负债 / EBITDA | B29: =IFERROR(('3_Balance'!B18+'3_Balance'!B19+'3_Balance'!B21)/('2_Income'!B14+'4_CashFlow'!B7+'4_CashFlow'!B8),"") | C29: =IFERROR(('3_Balance'!C18+'3_Balance'!C19+'3_Balance'!C21)/('2_Income'!C14+'4_CashFlow'!C7+'4_CashFlow'!C8),"") | D29: =IFERROR(('3_Balance'!D18+'3_Balance'!D19+'3_Balance'!D21)/('2_Income'!D14+'4_CashFlow'!D7+'4_CashFlow'!D8),"") | E29: =IFERROR(('3_Balance'!E18+'3_Balance'!E19+'3_Balance'!E21)/('2_Income'!E14+'4_CashFlow'!E7+'4_CashFlow'!E8),"") | F29: =IFERROR(('3_Balance'!F18+'3_Balance'!F19+'3_Balance'!F21)/('2_Income'!F14+'4_CashFlow'!F7+'4_CashFlow'!F8),"") | G29: =IFERROR(('3_Balance'!G18+'3_Balance'!G19+'3_Balance'!G21)/('2_Income'!G14+'4_CashFlow'!G7+'4_CashFlow'!G8),"") | H29: =IFERROR(('3_Balance'!H18+'3_Balance'!H19+'3_Balance'!H21)/('2_Income'!H14+'4_CashFlow'!H7+'4_CashFlow'!H8),"") | I29: =IFERROR(('3_Balance'!I18+'3_Balance'!I19+'3_Balance'!I21)/('2_Income'!I14+'4_CashFlow'!I7+'4_CashFlow'!I8),"") | ... K29: =IFERROR(('3_Balance'!K18+'3_Balance'!K19+'3_Balance'!K21)/('2_Income'!K14+'4_CashFlow'!K7+'4_CashFlow'!K8),"")
A30: EBIT 利息保障倍数 | B30: =IFERROR('2_Income'!B14/'2_Income'!B15,"") | C30: =IFERROR('2_Income'!C14/'2_Income'!C15,"") | D30: =IFERROR('2_Income'!D14/'2_Income'!D15,"") | E30: =IFERROR('2_Income'!E14/'2_Income'!E15,"") | F30: =IFERROR('2_Income'!F14/'2_Income'!F15,"") | G30: =IFERROR('2_Income'!G14/'2_Income'!G15,"") | H30: =IFERROR('2_Income'!H14/'2_Income'!H15,"") | I30: =IFERROR('2_Income'!I14/'2_Income'!I15,"") | ... K30: =IFERROR('2_Income'!K14/'2_Income'!K15,"")
A31: 权益乘数（平均总资产 / 平均权益） | B31: =IFERROR('3_Balance'!B16/'3_Balance'!B25,"") | C31: =IFERROR(AVERAGE('3_Balance'!B16,'3_Balance'!C16)/AVERAGE('3_Balance'!B25,'3_Balance'!C25),"") | D31: =IFERROR(AVERAGE('3_Balance'!C16,'3_Balance'!D16)/AVERAGE('3_Balance'!C25,'3_Balance'!D25),"") | E31: =IFERROR(AVERAGE('3_Balance'!D16,'3_Balance'!E16)/AVERAGE('3_Balance'!D25,'3_Balance'!E25),"") | F31: =IFERROR(AVERAGE('3_Balance'!E16,'3_Balance'!F16)/AVERAGE('3_Balance'!E25,'3_Balance'!F25),"") | G31: =IFERROR(AVERAGE('3_Balance'!F16,'3_Balance'!G16)/AVERAGE('3_Balance'!F25,'3_Balance'!G25),"") | H31: =IFERROR(AVERAGE('3_Balance'!G16,'3_Balance'!H16)/AVERAGE('3_Balance'!G25,'3_Balance'!H25),"") | I31: =IFERROR(AVERAGE('3_Balance'!H16,'3_Balance'!I16)/AVERAGE('3_Balance'!H25,'3_Balance'!I25),"") | J31: =IFERROR(AVERAGE('3_Balance'!I16,'3_Balance'!J16)/AVERAGE('3_Balance'!I25,'3_Balance'!J25),"") | K31: =IFERROR(AVERAGE('3_Balance'!J16,'3_Balance'!K16)/AVERAGE('3_Balance'!J25,'3_Balance'!K25),"")
A33: 四、现金流质量 Cash quality
A34: 指标 | B34: FY2021A | C34: FY2022A | D34: FY2023A | E34: FY2024A | F34: FY2025A | G34: FY2026E | H34: FY2027E | I34: FY2028E | J34: FY2029E | K34: FY2030E
A35: 经营现金流 / 净利润 | B35: =IFERROR('4_CashFlow'!B15/'2_Income'!B20,"") | C35: =IFERROR('4_CashFlow'!C15/'2_Income'!C20,"") | D35: =IFERROR('4_CashFlow'!D15/'2_Income'!D20,"") | E35: =IFERROR('4_CashFlow'!E15/'2_Income'!E20,"") | F35: =IFERROR('4_CashFlow'!F15/'2_Income'!F20,"") | G35: =IFERROR('4_CashFlow'!G15/'2_Income'!G20,"") | H35: =IFERROR('4_CashFlow'!H15/'2_Income'!H20,"") | I35: =IFERROR('4_CashFlow'!I15/'2_Income'!I20,"") | ... K35: =IFERROR('4_CashFlow'!K15/'2_Income'!K20,"")
A36: 自由现金流 / 营收 | B36: =IFERROR('4_CashFlow'!B18/'2_Income'!B6,"") | C36: =IFERROR('4_CashFlow'!C18/'2_Income'!C6,"") | D36: =IFERROR('4_CashFlow'!D18/'2_Income'!D6,"") | E36: =IFERROR('4_CashFlow'!E18/'2_Income'!E6,"") | F36: =IFERROR('4_CashFlow'!F18/'2_Income'!F6,"") | G36: =IFERROR('4_CashFlow'!G18/'2_Income'!G6,"") | H36: =IFERROR('4_CashFlow'!H18/'2_Income'!H6,"") | I36: =IFERROR('4_CashFlow'!I18/'2_Income'!I6,"") | ... K36: =IFERROR('4_CashFlow'!K18/'2_Income'!K6,"")
A37: 资本开支 / 折旧摊销 | B37: =IFERROR(-'4_CashFlow'!B16/('4_CashFlow'!B7+'4_CashFlow'!B8),"") | C37: =IFERROR(-'4_CashFlow'!C16/('4_CashFlow'!C7+'4_CashFlow'!C8),"") | D37: =IFERROR(-'4_CashFlow'!D16/('4_CashFlow'!D7+'4_CashFlow'!D8),"") | E37: =IFERROR(-'4_CashFlow'!E16/('4_CashFlow'!E7+'4_CashFlow'!E8),"") | F37: =IFERROR(-'4_CashFlow'!F16/('4_CashFlow'!F7+'4_CashFlow'!F8),"") | G37: =IFERROR(-'4_CashFlow'!G16/('4_CashFlow'!G7+'4_CashFlow'!G8),"") | H37: =IFERROR(-'4_CashFlow'!H16/('4_CashFlow'!H7+'4_CashFlow'!H8),"") | I37: =IFERROR(-'4_CashFlow'!I16/('4_CashFlow'!I7+'4_CashFlow'!I8),"") | ... K37: =IFERROR(-'4_CashFlow'!K16/('4_CashFlow'!K7+'4_CashFlow'!K8),"")
A38: FCFF / 税后 EBIT | B38: =IFERROR('4_CashFlow'!B19/('2_Income'!B14*(1-'5_DCF'!$B$34)),"") | C38: =IFERROR('4_CashFlow'!C19/('2_Income'!C14*(1-'5_DCF'!$B$34)),"") | D38: =IFERROR('4_CashFlow'!D19/('2_Income'!D14*(1-'5_DCF'!$B$34)),"") | E38: =IFERROR('4_CashFlow'!E19/('2_Income'!E14*(1-'5_DCF'!$B$34)),"") | F38: =IFERROR('4_CashFlow'!F19/('2_Income'!F14*(1-'5_DCF'!$B$34)),"") | G38: =IFERROR('4_CashFlow'!G19/('2_Income'!G14*(1-'5_DCF'!$B$34)),"") | H38: =IFERROR('4_CashFlow'!H19/('2_Income'!H14*(1-'5_DCF'!$B$34)),"") | I38: =IFERROR('4_CashFlow'!I19/('2_Income'!I14*(1-'5_DCF'!$B$34)),"") | ... K38: =IFERROR('4_CashFlow'!K19/('2_Income'!K14*(1-'5_DCF'!$B$34)),"")
